Workbook

Sheet Income Statement Historical
B1: Income Statement- USD($) and shares in millions | C1: Actual | H1: Expected
C2: 2020 | D2: =C2+1 -> 2021 | E2: =D2+1 -> 2022 | F2: =E2+1 -> 2023 | G2: =F2+1 -> 2024 | H2: =G2+1 -> 2025 | I2: =H2+1 -> 2026 | J2: =I2+1 -> 2027 | K2: =J2+1 -> 2028 | L2: =K2+1 -> 2029
B3: REVENUE
B4: Revenues | C4: 12297 | D4: 13737 | E4: 14396 | F4: 15438 | G4: 16662 | H4: ='Revenue Build'!H19 -> 18105.79 | I4: ='Revenue Build'!I19 -> 19502.33 | J4: ='Revenue Build'!J19 -> 20770.692 | K4: ='Revenue Build'!K19 -> 21934.893 | L4: ='Revenue Build'!L19 -> 22849.177
A5: x | B5: Total revenue | C5: =SUM(C4:C4) -> 12297 | D5: =SUM(D4:D4) -> 13737 | E5: =SUM(E4:E4) -> 14396 | F5: =SUM(F4:F4) -> 15438 | G5: =SUM(G4:G4) -> 16662 | H5: =SUM(H4:H4) -> 18105.79 | I5: =SUM(I4:I4) -> 19502.33 | J5: =SUM(J4:J4) -> 20770.692 | ... L5: =SUM(L4:L4) -> 22849.177
B6: Revenue Growth | D6: =(D5/C5)-1 -> 0.11710173 | E6: =(E5/D5)-1 -> 0.047972629 | F6: =(F5/E5)-1 -> 0.072381217 | G6: =(G5/F5)-1 -> 0.079284881 | H6: =(H5/G5)-1 -> 0.086651662 | I6: =(I5/H5)-1 -> 0.077132221 | J6: =(J5/I5)-1 -> 0.065036447 | K6: =(K5/J5)-1 -> 0.056050198 | L6: =(L5/K5)-1 -> 0.041681683
B8: OPERATING EXPENSES | O8: `
B9: COGS | C9: 10560 | D9: 11723 | E9: 12312 | F9: 13194 | G9: 13864 | H9: ='Expense Build'!G5 -> 14919.171 | I9: ='Expense Build'!H5 -> 15991.91 | J9: ='Expense Build'!I5 -> 16948.885 | K9: ='Expense Build'!J5 -> 17811.133 | L9: ='Expense Build'!K5 -> 18462.135
B10: Selling, general and administrative | C10: 770 | D10: 860 | E10: 951 | F10: 942 | G10: 983 | H10: ='Expense Build'!G6 -> 1127.2533 | I10: ='Expense Build'!H6 -> 1214.2008 | J10: ='Expense Build'!I6 -> 1293.1681 | K10: ='Expense Build'!J6 -> 1365.6504 | L10: ='Expense Build'!K6 -> 1422.573
B11: Acquisition, integration, and restructuring costs | C11: -68 | D11: -9 | E11: 17 | F11: 24 | G11: 16 | H11: ='Expense Build'!G7 -> -4 | I11: ='Expense Build'!H7 -> 8.8 | J11: ='Expense Build'!I7 -> 12.36 | K11: ='Expense Build'!J7 -> 11.432 | L11: ='Expense Build'!K7 -> 8.9184
B12: Goodwill impairment charges | C12: 39 | D12: 27 | E12: 0 | F12: 596 | G12: 0 | H12: ='Expense Build'!G8 -> 0 | I12: ='Expense Build'!H8 -> 0 | J12: ='Expense Build'!I8 -> 0 | K12: ='Expense Build'!J8 -> 0 | L12: ='Expense Build'!K8 -> 0
B13: Asset Impairment Charged | C13: 12 | D13: 4 | E13: 40 | F13: 91 | G13: 11 | H13: ='Expense Build'!G9 -> 31.6 | I13: ='Expense Build'!H9 -> 35.52 | J13: ='Expense Build'!I9 -> 41.824 | K13: ='Expense Build'!J9 -> 42.1888 | L13: ='Expense Build'!K9 -> 32.42656
B14: Equity earnings of non-consolidated subsidiaries | C14: -14 | D14: -20 | E14: -12 | F14: -30 | G14: -39 | H14: ='Expense Build'!G10 -> -23 | I14: ='Expense Build'!H10 -> -24.8 | J14: ='Expense Build'!I10 -> -25.76 | K14: ='Expense Build'!J10 -> -28.512 | L14: ='Expense Build'!K10 -> -28.2144
B15: Total Operating Expense | C15: =SUM(C9:C14) -> 11299 | D15: =SUM(D9:D14) -> 12585 | E15: =SUM(E9:E14) -> 13308 | F15: =SUM(F9:F14) -> 14817 | G15: =SUM(G9:G14) -> 14835 | H15: =SUM(H9:H10) -> 16046.424 | I15: =SUM(I9:I10) -> 17206.111 | J15: =SUM(J9:J10) -> 18242.053 | K15: =SUM(K9:K10) -> 19176.784 | L15: =SUM(L9:L10) -> 19884.708
A16: x | B16: EBIT | C16: =C5-C15 -> 998 | D16: =D5-D15 -> 1152 | E16: =E5-E15 -> 1088 | F16: =F5-F15 -> 621 | G16: =G5-G15 -> 1827 | H16: =H5-H15 -> 2059.3658 | I16: =I5-I15 -> 2296.2186 | J16: =J5-J15 -> 2528.6392 | ... L16: =L5-L15 -> 2964.4689
B17: EBIT Margin | C17: =C16/C5 -> 0.081158006 | D17: =D16/D5 -> 0.083861105 | E17: =E16/E5 -> 0.075576549 | F17: =F16/F5 -> 0.040225418 | G17: =G16/G5 -> 0.1096507 | H17: =H16/H5 -> 0.11374073 | I17: =I16/I5 -> 0.11774073 | J17: =J16/J5 -> 0.12174073 | ... L17: =L16/L5 -> 0.12974073
E18: =(E16+333)/E5 -> 0.098707974 | F18: =(F16+331)/F5 -> 0.061666019 | G18: =(G16+290)/G5 -> 0.12705558 | H18: 13-13.5 ebitda
B19: OTHER INCOME (EXPENSE)
B20: Interest expense | C20: -179 | D20: -184 | E20: -199 | F20: -212 | G20: -193 | H20: ='Expense Build'!G14 -> -193.38795 | I20: ='Expense Build'!H14 -> -193.38795 | J20: ='Expense Build'!I14 -> -193.38795 | K20: ='Expense Build'!J14 -> -193.38795 | L20: ='Expense Build'!K14 -> -193.38795
B21: Interest income and other, net | C21: -38 | D21: -1 | E21: -3 | F21: -6 | G21: 5 | H21: ='Expense Build'!G15 -> 5 | I21: ='Expense Build'!H15 -> 5 | J21: ='Expense Build'!I15 -> 5 | K21: ='Expense Build'!J15 -> 5 | L21: ='Expense Build'!K15 -> 5
B22: Interest, net | C22: =SUM(C20:C21) -> -217 | D22: =SUM(D20:D21) -> -185 | E22: =SUM(E20:E21) -> -202 | F22: =SUM(F20:F21) -> -218 | G22: =SUM(G20:G21) -> -188 | H22: ='Expense Build'!G16 -> -188.38795 | I22: ='Expense Build'!H16 -> -188.38795 | J22: ='Expense Build'!I16 -> -188.38795 | K22: ='Expense Build'!J16 -> -188.38795 | L22: ='Expense Build'!K16 -> -188.38795
A23: x | B23: INCOME BEFORE INCOME TAXES (EBT) | C23: =C16+C22 -> 781 | D23: =D16+D22 -> 967 | E23: =E16+E22 -> 886 | F23: =F16+F22 -> 403 | G23: =G16+G22 -> 1639 | H23: =H16+H22 -> 1870.9778 | I23: =I16+I22 -> 2107.8306 | J23: =J16+J22 -> 2340.2513 | ... L23: =L16+L22 -> 2776.0809
B25: Provision for income taxes | C25: -152 | D25: -208 | E25: -193 | F25: -195 | G25: -388 | H25: ='Expense Build'!G17 -> 484.68002 | I25: ='Expense Build'!H17 -> 532.63321 | J25: ='Expense Build'!I17 -> 580.92863 | K25: ='Expense Build'!J17 -> 631.22678 | L25: ='Expense Build'!K17 -> 678.40316
B26: Net income including noncontrolling interests | C26: =C23+C25 -> 629 | D26: =D23+D25 -> 759 | E26: =E23+E25 -> 693 | F26: =F23+F25 -> 208 | G26: =G23+G25 -> 1251 | H26: =H23-H25 -> 1386.2978 | I26: =I23-I25 -> 1575.1974 | J26: =J23-J25 -> 1759.3226 | K26: =K23-K25 -> 1938.4948 | L26: =L23-L25 -> 2097.6778
B27: Net income attributable to noncontrolling interests | C27: 1 | D27: 6 | E27: 8 | F27: 9 | G27: -3 | H27: =G27 -> -3 | I27: =H27 -> -3 | J27: =I27 -> -3 | K27: =J27 -> -3 | L27: =K27 -> -3
A28: x | B28: NET INCOME ATTRIBUTABLE TO LEIDOS | C28: =C26-C27 -> 628 | D28: =D26-D27 -> 753 | E28: =E26-E27 -> 685 | F28: =F26-F27 -> 199 | G28: =G26-G27 -> 1254 | H28: =H26-H27 -> 1389.2978 | I28: =I26-I27 -> 1578.1974 | J28: =J26-J27 -> 1762.3226 | ... L28: =L26-L27 -> 2100.6778
B29: Net Income Margin | C29: =C28/C5 -> 0.051069367 | D29: =D28/D5 -> 0.054815462 | E29: =E28/E5 -> 0.047582662 | F29: =F28/F5 -> 0.012890271 | G29: =G28/G5 -> 0.075261073 | H29: =H28/H5 -> 0.07673224 | I29: =I28/I5 -> 0.080923532 | J29: =J28/J5 -> 0.084846602 | ... L29: =L28/L5 -> 0.091936694
A31: x | B31: NET INCOME PER COMMON SHARE ATTRIBUTABLE TO LEIDOS:
B32: Basic | C32: 4.42 | D32: 5.34 | E32: 5 | F32: 1.45 | G32: 9.36 | H32: =(H28*1000)/H36 -> 10.522512 | I32: =(I28*1000)/I36 -> 12.129172 | J32: =(J28*1000)/J36 -> 13.743616 | K32: =(K28*1000)/K36 -> 15.363762 | L32: =(L28*1000)/L36 -> 16.868114
B33: Diluted | C33: 4.36 | D33: 5.27 | E33: 4.96 | F33: 1.44 | G33: 9.22 | H33: =(H28*1000)/H37 -> 10.361435 | I33: =(I28*1000)/I37 -> 11.939251 | J33: =(J28*1000)/J37 -> 13.523601 | K33: =(K28*1000)/K37 -> 15.112432 | L33: =(L28*1000)/L37 -> 16.586271
D34: =(D33-C33)/D33 -> 0.17267552 | E34: =(E33-D33)/E33 -> -0.0625 | F34: =(F33-E33)/F33 -> -2.4444444 | G34: =(G33-F33)/G33 -> 0.84381779
B35: Shares used in calculation (000’s)
B36: Basic | C36: =C28/C32 * 1000 -> 142081.45 | D36: =D28/D32 * 1000 -> 141011.24 | E36: =E28/E32 * 1000 -> 137000 | F36: =F28/F32 * 1000 -> 137241.38 | G36: =G28/G32 * 1000 -> 133974.36 | H36: =G36+G36*$I$39 -> 132031.01 | I36: =H36+H36*$I$39 -> 130115.84 | J36: =I36+I36*$I$39 -> 128228.46 | K36: =J36+J36*$I$39 -> 126368.45 | L36: =K36+K36*$I$39 -> 124535.43
B37: Diluted | C37: =C28/C33 * 1000 -> 144036.7 | D37: =D28/D33 * 1000 -> 142884.25 | E37: =E28/E33 * 1000 -> 138104.84 | F37: =F28/F33 * 1000 -> 138194.44 | G37: =G28/G33 * 1000 -> 136008.68 | H37: =G37+G37*$I$40 -> 134083.53 | I37: =H37+H37*$I$40 -> 132185.63 | J37: =I37+I37*$I$40 -> 130314.6 | K37: =J37+J37*$I$40 -> 128470.05 | L37: =K37+K37*$I$40 -> 126651.6
D39: =(D36-C36)/C36 -> -0.0075323839 | E39: =(E36-D36)/D36 -> -0.028446215 | F39: =(F36-E36)/E36 -> 0.0017618928 | G39: =(G36-F36)/F36 -> -0.023804922 | H39: avg | I39: =AVERAGE(D39:G39) -> -0.014505407
D40: =(D37-C37)/C37 -> -0.0080010636 | E40: =(E37-D37)/D37 -> -0.033449535 | F40: =(F37-E37)/E37 -> 0.00064882401 | G40: =(G37-F37)/F37 -> -0.01581661 | H40: avg | I40: =AVERAGE(D40:G40) -> -0.014154596
B44: FCF Conversion | C44: 2020 | D44: =C44+1 -> 2021 | E44: =D44+1 -> 2022 | F44: =E44+1 -> 2023 | G44: =F44+1 -> 2024 | I44: ROIC | J44: 2020 | K44: =J44+1 -> 2021 | L44: =K44+1 -> 2022 | M44: =L44+1 -> 2023 | N44: =M44+1 -> 2024
I45: EBIT | J45: =C16 -> 998 | K45: =D16 -> 1152 | L45: =E16 -> 1088 | M45: =F16 -> 621 | N45: =G16 -> 1827
B46: operating cash flow | C46: 1334 | D46: 1031 | E46: 992 | F46: 1165 | G46: 1392 | I46: 1-tax rate | J46: =(1-'Expense Build'!B26) -> 0.80537772 | K46: =(1-'Expense Build'!C26) -> 0.78490176 | L46: =(1-'Expense Build'!D26) -> 0.78216704 | M46: =(1-'Expense Build'!E26) -> 0.51612903 | N46: =(1-'Expense Build'!F26) -> 0.76327029
B47: less: capex | C47: 183 | D47: 104 | E47: 129 | F47: 207 | G47: 149 | I47: NOPAT | J47: =J45*J46 -> 803.76697 | K47: =K45*K46 -> 904.20683 | L47: =L45*L46 -> 850.99774 | M47: =M45*M46 -> 320.51613 | N47: =N45*N46 -> 1394.4948
...

Sheet Expense Build
A1: Expense Build - USD ($) in millions | D1: Actual | I1: Estimated
B2: 2020A | C2: 2021A | D2: 2022A | E2: 2023A | F2: 2024A | G2: 2025E | H2: 2026E | I2: 2027E | J2: 2028E | K2: 2029E
A4: Operating Expenses:
A5: COGS | B5: ='Income Statement Historical'!C9 -> 10560 | C5: ='Income Statement Historical'!D9 -> 11723 | D5: ='Income Statement Historical'!E9 -> 12312 | E5: ='Income Statement Historical'!F9 -> 13194 | F5: ='Income Statement Historical'!G9 -> 13864 | G5: =G23*G28 -> 14919.171 | H5: =H23*H28 -> 15991.91 | I5: =I23*I28 -> 16948.885 | J5: =J23*J28 -> 17811.133 | K5: =K23*K28 -> 18462.135
A6: Selling, general and administrative | B6: ='Income Statement Historical'!C10 -> 770 | C6: ='Income Statement Historical'!D10 -> 860 | D6: ='Income Statement Historical'!E10 -> 951 | E6: ='Income Statement Historical'!F10 -> 942 | F6: ='Income Statement Historical'!G10 -> 983 | G6: =G24*G28 -> 1127.2533 | H6: =H24*H28 -> 1214.2008 | I6: =I24*I28 -> 1293.1681 | J6: =J24*J28 -> 1365.6504 | K6: =K24*K28 -> 1422.573
A7: Acquisition, integration, and restructuring costs | B7: ='Income Statement Historical'!C11 -> -68 | C7: ='Income Statement Historical'!D11 -> -9 | D7: ='Income Statement Historical'!E11 -> 17 | E7: ='Income Statement Historical'!F11 -> 24 | F7: ='Income Statement Historical'!G11 -> 16 | G7: =AVERAGE(B7:F7) -> -4 | H7: =AVERAGE(C7:G7) -> 8.8 | I7: =AVERAGE(D7:H7) -> 12.36 | J7: =AVERAGE(E7:I7) -> 11.432 | K7: =AVERAGE(F7:J7) -> 8.9184
A8: Goodwill impairment charges | B8: ='Income Statement Historical'!C12 -> 39 | C8: ='Income Statement Historical'!D12 -> 27 | D8: ='Income Statement Historical'!E12 -> 0 | E8: ='Income Statement Historical'!F12 -> 596 | F8: ='Income Statement Historical'!G12 -> 0 | G8: =F8 -> 0 | H8: =G8 -> 0 | I8: =H8 -> 0 | J8: =I8 -> 0 | K8: =J8 -> 0
A9: Asset Impairment Charged | B9: ='Income Statement Historical'!C13 -> 12 | C9: ='Income Statement Historical'!D13 -> 4 | D9: ='Income Statement Historical'!E13 -> 40 | E9: ='Income Statement Historical'!F13 -> 91 | F9: ='Income Statement Historical'!G13 -> 11 | G9: =AVERAGE(B9:F9) -> 31.6 | H9: =AVERAGE(C9:G9) -> 35.52 | I9: =AVERAGE(D9:H9) -> 41.824 | J9: =AVERAGE(E9:I9) -> 42.1888 | K9: =AVERAGE(F9:J9) -> 32.42656
A10: Equity earnings of non-consolidated subsidiaries | B10: ='Income Statement Historical'!C14 -> -14 | C10: ='Income Statement Historical'!D14 -> -20 | D10: ='Income Statement Historical'!E14 -> -12 | E10: ='Income Statement Historical'!F14 -> -30 | F10: ='Income Statement Historical'!G14 -> -39 | G10: =AVERAGE(B10:F10) -> -23 | H10: =AVERAGE(C10:G10) -> -24.8 | I10: =AVERAGE(D10:H10) -> -25.76 | J10: =AVERAGE(E10:I10) -> -28.512 | K10: =AVERAGE(F10:J10) -> -28.2144
A11: Total Operating Expenses: | B11: =SUM(B5:B10) -> 11299 | C11: =SUM(C5:C10) -> 12585 | D11: =SUM(D5:D10) -> 13308 | E11: =SUM(E5:E10) -> 14817 | F11: =SUM(F5:F10) -> 14835 | G11: =SUM(G5:G10) -> 16051.024 | H11: =SUM(H5:H10) -> 17225.631 | I11: =SUM(I5:I10) -> 18270.477 | ... K11: =SUM(K5:K10) -> 19897.838
A13: Non-operating Expenses:
A14: Interest expense | B14: ='Income Statement Historical'!C20 -> -179 | C14: ='Income Statement Historical'!D20 -> -184 | D14: ='Income Statement Historical'!E20 -> -199 | E14: ='Income Statement Historical'!F20 -> -212 | F14: ='Income Statement Historical'!G20 -> -193 | G14: =G25*G31 -> -193.38795 | H14: =H25*H31 -> -193.38795 | I14: =I25*I31 -> -193.38795 | J14: =J25*J31 -> -193.38795 | K14: =K25*K31 -> -193.38795
A15: Interest income and other, net | B15: ='Income Statement Historical'!C21 -> -38 | C15: ='Income Statement Historical'!D21 -> -1 | D15: ='Income Statement Historical'!E21 -> -3 | E15: ='Income Statement Historical'!F21 -> -6 | F15: ='Income Statement Historical'!G21 -> 5 | G15: =F15 -> 5 | H15: =G15 -> 5 | I15: =H15 -> 5 | J15: =I15 -> 5 | K15: =J15 -> 5
A16: Interest, net | B16: ='Income Statement Historical'!C22 -> -217 | C16: ='Income Statement Historical'!D22 -> -185 | D16: ='Income Statement Historical'!E22 -> -202 | E16: ='Income Statement Historical'!F22 -> -218 | F16: ='Income Statement Historical'!G22 -> -188 | G16: =SUM(G14:G15) -> -188.38795 | H16: =SUM(H14:H15) -> -188.38795 | I16: =SUM(I14:I15) -> -188.38795 | J16: =SUM(J14:J15) -> -188.38795 | K16: =SUM(K14:K15) -> -188.38795
A17: Provision for income taxes | B17: =-'Income Statement Historical'!C25 -> 152 | C17: =-'Income Statement Historical'!D25 -> 208 | D17: =-'Income Statement Historical'!E25 -> 193 | E17: =-'Income Statement Historical'!F25 -> 195 | F17: =-'Income Statement Historical'!G25 -> 388 | G17: =G26*G33 -> 484.68002 | H17: =H26*H33 -> 532.63321 | I17: =I26*I33 -> 580.92863 | J17: =J26*J33 -> 631.22678 | K17: =K26*K33 -> 678.40316
A18: Total Non-operating Expenses: | B18: =-B16+B17 -> 369 | C18: =-C16+C17 -> 393 | D18: =-D16+D17 -> 395 | E18: =-E16+E17 -> 413 | F18: =-F16+F17 -> 576 | G18: =-G16+G17 -> 673.06797 | H18: =-H16+H17 -> 721.02116 | I18: =-I16+I17 -> 769.31659 | ... K18: =-K16+K17 -> 866.79111
A20: Total Expenses: | B20: =SUM(B18,B11) -> 11668 | C20: =SUM(C18,C11) -> 12978 | D20: =SUM(D18,D11) -> 13703 | E20: =SUM(E18,E11) -> 15230 | F20: =SUM(F18,F11) -> 15411 | G20: =SUM(G18,G11) -> 16724.092 | H20: =SUM(H18,H11) -> 17946.652 | I20: =SUM(I18,I11) -> 19039.793 | ... K20: =SUM(K18,K11) -> 20764.63
A22: Expense Build Drivers:
A23: COGS - % of revenue | B23: =B5/B28 -> 0.85874604 | C23: =C5/C28 -> 0.85338866 | D23: =D5/D28 -> 0.85523757 | E23: =E5/E28 -> 0.85464438 | F23: =F5/F28 -> 0.83207298 | G23: 0.824 | H23: =G23-0.004 -> 0.82 | I23: =H23-0.004 -> 0.816 | J23: =I23-0.004 -> 0.812 | K23: =J23-0.004 -> 0.808
A24: SGandA - % of revenue | B24: =B6/B28 -> 0.062616898 | C24: =C6/C28 -> 0.062604644 | D24: =D6/D28 -> 0.066060017 | E24: =E6/E28 -> 0.061018267 | F24: =F6/F28 -> 0.058996519 | G24: =AVERAGE(B24:F24) -> 0.062259269 | H24: =G24 -> 0.062259269 | I24: =H24 -> 0.062259269 | J24: =I24 -> 0.062259269 | K24: =J24 -> 0.062259269
A25: Interest Expense (Income) - % of debt | B25: =B14/B31 -> -0.023705469 | C25: =C14/C31 -> -0.023523396 | D25: =D14/D31 -> -0.025269841 | E25: =E14/E31 -> -0.02751103 | F25: =F14/F31 -> -0.025215574 | G25: =AVERAGE(B25:F25) -> -0.025045062 | H25: =G25 -> -0.025045062 | I25: =H25 -> -0.025045062 | J25: =I25 -> -0.025045062 | K25: =J25 -> -0.025045062
A26: Income Tax Expense - Effective Tax Rate | B26: =B17/B33 -> 0.19462228 | C26: =C17/C33 -> 0.21509824 | D26: =D17/D33 -> 0.21783296 | E26: =E17/E33 -> 0.48387097 | F26: =F17/F33 -> 0.23672971 | G26: =AVERAGE(B26:D26,F26) -> 0.2160708 | H26: =G26 -> 0.2160708 | I26: =H26 -> 0.2160708 | J26: =I26 -> 0.2160708 | K26: =J26 -> 0.2160708 | L26: *excluded the 48% tax because that was anomaly
A28: Total revenue | B28: ='Income Statement Historical'!C5 -> 12297 | C28: ='Income Statement Historical'!D5 -> 13737 | D28: ='Income Statement Historical'!E5 -> 14396 | E28: ='Income Statement Historical'!F5 -> 15438 | F28: ='Income Statement Historical'!G5 -> 16662 | G28: ='Revenue Build'!H19 -> 18105.79 | H28: ='Revenue Build'!I19 -> 19502.33 | I28: ='Revenue Build'!J19 -> 20770.692 | J28: ='Revenue Build'!K19 -> 21934.893 | K28: ='Revenue Build'!L19 -> 22849.177
A29: Long-term debt, excluding current portion | B29: 4644 | C29: 4593 | D29: 3928 | E29: 4052 | F29: 4664 | G29: =AVERAGE(B29:F29) -> 4376.2 | H29: =G29 -> 4376.2 | I29: =H29 -> 4376.2 | J29: =I29 -> 4376.2 | K29: =J29 -> 4376.2
A30: Total current liabilities | B30: 2907 | C30: 3229 | D30: 3947 | E30: 3654 | F30: 2990 | G30: =AVERAGE(B30:F30) -> 3345.4 | H30: =G30 -> 3345.4 | I30: =H30 -> 3345.4 | J30: =I30 -> 3345.4 | K30: =J30 -> 3345.4
A31: TOTAL LTD | B31: =SUM(B29:B30) -> 7551 | C31: =SUM(C29:C30) -> 7822 | D31: =SUM(D29:D30) -> 7875 | E31: =SUM(E29:E30) -> 7706 | F31: =SUM(F29:F30) -> 7654 | G31: =AVERAGE(B31:F31) -> 7721.6 | H31: =G31 -> 7721.6 | I31: =H31 -> 7721.6 | J31: =I31 -> 7721.6 | K31: =J31 -> 7721.6
A33: EBT | B33: ='Income Statement Historical'!C23 -> 781 | C33: ='Income Statement Historical'!D23 -> 967 | D33: ='Income Statement Historical'!E23 -> 886 | E33: ='Income Statement Historical'!F23 -> 403 | F33: ='Income Statement Historical'!G23 -> 1639 | G33: =G28-G11-G16 -> 2243.1537 | H33: =H28-H11-H16 -> 2465.0865 | I33: =I28-I11-I16 -> 2688.6032 | J33: =J28-J11-J16 -> 2921.3887 | K33: =K28-K11-K16 -> 3139.7263

Sheet Revenue Build
B1: Revenue Build - USD ($) in millions | E1: Actual | J1: Estimated | P1: Revenue Build - USD ($) in millions | S1: Actual
C2: 2020E** | D2: 2021E** | E2: 2022A | F2: 2023A | G2: 2024A | H2: 2025E | I2: 2026E | J2: 2027E | K2: 2028E | L2: 2029E | Q2: 2020E** | R2: 2021E** | S2: 2022A | T2: 2023A | U2: 2024A
A3: 1 | B3: National Security & Digital | C3: ='Revenue Mapping of old segments'!AE7 -> 5746.8153 | D3: ='Revenue Mapping of old segments'!AF7 -> 6517.5523 | E3: =SUM(E4:E6) -> 6701 | F3: =SUM(F4:F6) -> 7142 | G3: =SUM(G4:G6) -> 7304 | H3: =SUM(H4:H6) -> 7792.22 | I3: =SUM(I4:I6) -> 8187.0032 | J3: =SUM(J4:J6) -> 8525.0047 | K3: =SUM(K4:K6) -> 8818.6374 | L3: =SUM(L4:L6) -> 9059.6253 | O3: 1 | P3: DoD and U.S. Intelligence Community | Q3: =SUM(C4,C8,C12,C16) -> 6297.2853 | R3: =SUM(D4,D8,D12,D16) -> 6940.0638 | S3: =SUM(E4,E8,E12,E16) -> 7120 | T3: =SUM(F4,F8,F12,F16) -> 7577 | U3: =SUM(G4,G8,G12,G16) -> 7962
B4: DoD and U.S. Intelligence Community | C4: ='Revenue Mapping of old segments'!AE8 -> 3860.9405 | D4: ='Revenue Mapping of old segments'!AF8 -> 4378.7525 | E4: 4502 | F4: 4799 | G4: 5074 | H4: =G4*(1+H23) -> 5479.92 | I4: =H4*(1+I23) -> 5808.7152 | J4: =I4*(1+J23) -> 6099.151 | K4: =J4*(1+K23) -> 6343.117 | L4: =K4*(1+L23) -> 6533.4105 | O4: 2 | P4: Other U.S. government agencies* | Q4: =SUM(C5,C9,C13,C17) -> 4411.1647 | R4: =SUM(D5,D9,D13,D17) -> 4660.0861 | S4: =SUM(E5,E9,E13,E17) -> 5240 | T4: =SUM(F5,F9,F13,F17) -> 5734 | U4: =SUM(G5,G9,G13,G17) -> 6488
B5: Other U.S. government agencies* | C5: ='Revenue Mapping of old segments'!AE9 -> 1744.3698 | D5: ='Revenue Mapping of old segments'!AF9 -> 1978.3169 | E5: 2034 | F5: 2212 | G5: 2115 | H5: =G5*(1+H24) -> 2199.6 | I5: =H5*(1+I24) -> 2265.588 | J5: =I5*(1+J24) -> 2310.8998 | K5: =J5*(1+K24) -> 2357.1178 | L5: =K5*(1+L24) -> 2404.2601 | O5: 3 | P5: Commercial and non-U.S. customers | Q5: =SUM(C6,C10,C14,C18) -> 1488.5501 | R5: =SUM(D6,D10,D14,D18) -> 2016.8501 | S5: =SUM(E6,E10,E14,E18) -> 1937 | T5: =SUM(F6,F10,F14,F18) -> 2028 | U5: =SUM(G6,G10,G14,G18) -> 2126
B6: Commercial and non-U.S. customers | C6: ='Revenue Mapping of old segments'!AE10 -> 141.50493 | D6: ='Revenue Mapping of old segments'!AF10 -> 160.48293 | E6: 165 | F6: 131 | G6: 115 | H6: =G6*(1+H25) -> 112.7 | I6: =H6*(1+I25) -> 112.7 | J6: =I6*(1+J25) -> 114.954 | K6: =J6*(1+K25) -> 118.40262 | L6: =K6*(1+L25) -> 121.9547 | O6: growth | V6: avg | W6: avg last three years
A7: 2 | B7: Health & Civil | C7: ='Revenue Mapping of old segments'!AE11 -> 3264.6671 | D7: ='Revenue Mapping of old segments'!AF11 -> 3144.1569 | E7: =SUM(E8:E10) -> 3913 | F7: =SUM(F8:F10) -> 4202 | G7: =SUM(G8:G10) -> 4994 | H7: =SUM(H8:H10) -> 5679.36 | I7: =SUM(I8:I10) -> 6341.0157 | J7: =SUM(J8:J10) -> 6977.1477 | K7: =SUM(K8:K10) -> 7571.8099 | L7: =SUM(L8:L10) -> 8032.6433 | O7: 1 | P7: DoD and U.S. Intelligence Community | R7: =(R3-Q3)/Q3 -> 0.10207233 | S7: =(S3-R3)/R3 -> 0.025927167 | T7: =(T3-S3)/S3 -> 0.064185393 | U7: =(U3-T3)/T3 -> 0.050811667 | V7: =AVERAGE(R7:U7) -> 0.060749138 | W7: =AVERAGE(T7:U7) -> 0.05749853
B8: DoD and U.S. Intelligence Community | C8: ='Revenue Mapping of old segments'!AE12 -> 873.5258 | D8: ='Revenue Mapping of old segments'!AF12 -> 841.28094 | E8: 1047 | F8: 1059 | G8: 1032 | H8: =G8*(1+H27) -> 1052.64 | I8: =H8*(1+I27) -> 1073.6928 | J8: =I8*(1+J27) -> 1084.4297 | K8: =J8*(1+K27) -> 1095.274 | L8: =K8*(1+L27) -> 1106.2268 | O8: 2 | P8: Other U.S. government agencies* | R8: =(R4-Q4)/Q4 -> 0.056429853 | S8: =(S4-R4)/R4 -> 0.12444275 | T8: =(T4-S4)/S4 -> 0.094274809 | U8: =(U4-T4)/U4 -> 0.11621455 | V8: =AVERAGE(R8:U8) -> 0.097840491 | W8: =AVERAGE(T8:U8) -> 0.10524468
B9: Other U.S. government agencies* | C9: ='Revenue Mapping of old segments'!AE13 -> 2338.5796 | D9: ='Revenue Mapping of old segments'!AF13 -> 2252.2545 | E9: 2803 | F9: 3082 | G9: 3899 | H9: =G9*(1+H28) -> 4561.83 | I9: =H9*(1+I28) -> 5200.4862 | J9: =I9*(1+J28) -> 5824.5445 | K9: =J9*(1+K28) -> 6406.999 | L9: =K9*(1+L28) -> 6855.4889 | O9: 4 | P9: Commercial and non-U.S. customers | R9: =(R5-Q5)/Q5 -> 0.35490917 | S9: =(S5-R5)/R5 -> -0.039591506 | T9: =(T5-S5)/S5 -> 0.046979866 | U9: =(U5-T5)/U5 -> 0.046095955 | V9: =AVERAGE(R9:U9) -> 0.10209837 | W9: =AVERAGE(T9:U9) -> 0.04653791
B10: Commercial and non-U.S. customers | C10: ='Revenue Mapping of old segments'!AE14 -> 52.561724 | D10: ='Revenue Mapping of old segments'!AF14 -> 50.621489 | E10: 63 | F10: 61 | G10: 63 | H10: =G10*(1+H29) -> 64.89 | I10: =H10*(1+I29) -> 66.8367 | J10: =I10*(1+J29) -> 68.173434 | K10: =J10*(1+K29) -> 69.536903 | L10: =K10*(1+L29) -> 70.927641
A11: 3 | B11: Commercial & International | C11: ='Revenue Mapping of old segments'!AE15 -> 1375.2547 | D11: ='Revenue Mapping of old segments'!AF15 -> 1974.83 | E11: =SUM(E12:E14) -> 1876 | F11: =SUM(F12:F14) -> 2116 | G11: =SUM(G12:G14) -> 2248 | H11: =SUM(H12:H14) -> 2475.97 | I11: =SUM(I12:I14) -> 2695.088 | J11: =SUM(J12:J14) -> 2881.1339 | K11: =SUM(K12:K14) -> 3041.7338 | L11: =SUM(L12:L14) -> 3157.3582
B12: DoD and U.S. Intelligence Community | C12: ='Revenue Mapping of old segments'!AE16 -> 30.056206 | D12: ='Revenue Mapping of old segments'!AF16 -> 43.159932 | E12: 41 | F12: 35 | G12: 44 | H12: =G12*(1+H31) -> 47.08 | I12: =H12*(1+I31) -> 49.9048 | J12: =I12*(1+J31) -> 52.40004 | K12: =J12*(1+K31) -> 55.020042 | L12: =K12*(1+L31) -> 57.220844
B13: Other U.S. government agencies* | C13: ='Revenue Mapping of old segments'!AE17 -> 205.99497 | D13: ='Revenue Mapping of old segments'!AF17 -> 295.80343 | E13: 281 | F13: 319 | G13: 379 | H13: =G13*(1+H32) -> 439.64 | I13: =H13*(1+I32) -> 496.7932 | J13: =I13*(1+J32) -> 551.44045 | K13: =J13*(1+K32) -> 595.55569 | L13: =K13*(1+L32) -> 637.24459
B14: Commercial and non-U.S. customers | C14: ='Revenue Mapping of old segments'!AE18 -> 1139.2035 | D14: ='Revenue Mapping of old segments'!AF18 -> 1635.8667 | E14: 1554 | F14: 1762 | G14: 1825 | H14: =G14*(1+H33) -> 1989.25 | I14: =H14*(1+I33) -> 2148.39 | J14: =I14*(1+J33) -> 2277.2934 | K14: =J14*(1+K33) -> 2391.1581 | L14: =K14*(1+L33) -> 2462.8928
A15: 4 | B15: Defense Solutions | C15: ='Revenue Mapping of old segments'!AE19 -> 1810.2629 | D15: ='Revenue Mapping of old segments'!AF19 -> 1980.4607 | E15: =SUM(E16:E18) -> 1807 | F15: =SUM(F16:F18) -> 1879 | G15: =SUM(G16:G18) -> 2030 | H15: =SUM(H16:H18) -> 2158.24 | I15: =SUM(I16:I18) -> 2279.2229 | J15: =SUM(J16:J18) -> 2387.4057 | K15: =SUM(K16:K18) -> 2502.7123 | L15: =SUM(L16:L18) -> 2599.5498
B16: DoD and U.S. Intelligence Community | C16: ='Revenue Mapping of old segments'!AE20 -> 1532.7627 | D16: ='Revenue Mapping of old segments'!AF20 -> 1676.8704 | E16: 1530 | F16: 1684 | G16: 1812 | H16: =G16*(1+H35) -> 1938.84 | I16: =H16*(1+I35) -> 2055.1704 | J16: =I16*(1+J35) -> 2157.9289 | K16: =J16*(1+K35) -> 2265.8254 | L16: =K16*(1+L35) -> 2356.4584
B17: Other U.S. government agencies* | C17: ='Revenue Mapping of old segments'!AE21 -> 122.2203 | D17: ='Revenue Mapping of old segments'!AF21 -> 133.71124 | E17: 122 | F17: 121 | G17: 95 | H17: =G17*(1+H36) -> 90.25 | I17: =H17*(1+I36) -> 88.445 | J17: =I17*(1+J36) -> 88.445 | K17: =J17*(1+K36) -> 90.2139 | L17: =K17*(1+L36) -> 92.018178
B18: Commercial and non-U.S. customers | C18: ='Revenue Mapping of old segments'!AE22 -> 155.27989 | D18: ='Revenue Mapping of old segments'!AF22 -> 169.87903 | E18: 155 | F18: 74 | G18: 123 | H18: =G18*(1+H37) -> 129.15 | I18: =H18*(1+I37) -> 135.6075 | J18: =I18*(1+J37) -> 141.0318 | K18: =J18*(1+K37) -> 146.67307 | L18: =K18*(1+L37) -> 151.07326
A19: x | B19: Total Revenues | C19: ='Revenue Mapping of old segments'!AE23 -> 12197 | D19: ='Revenue Mapping of old segments'!AF23 -> 13617 | E19: =SUM(E3,E7,E11,E15) -> 14297 | F19: =SUM(F3,F7,F11,F15) -> 15339 | G19: =SUM(G3,G7,G11,G15) -> 16576 | H19: =SUM(H3,H7,H11,H15) -> 18105.79 | I19: =SUM(I3,I7,I11,I15) -> 19502.33 | J19: =SUM(J3,J7,J11,J15) -> 20770.692 | K19: =SUM(K3,K7,K11,K15) -> 21934.893 | L19: =SUM(L3,L7,L11,L15) -> 22849.177
A21: x | B21: Revenue Drivers
B22: National Security & Digital | D22: =(D3-C3)/C3 -> 0.13411551 | E22: =(E3-D3)/D3 -> 0.028146711 | F22: =(F3-E3)/E3 -> 0.065811073 | G22: =(G3-F3)/F3 -> 0.022682722 | H22: =(H3-G3)/G3 -> 0.066842826 | I22: =(I3-H3)/H3 -> 0.050663765 | J22: =(J3-I3)/I3 -> 0.041285133 | K22: =(K3-J3)/J3 -> 0.034443694 | L22: =(L3-K3)/K3 -> 0.027327118
B23: DoD and U.S. Intelligence Community | D23: =(D4-C4)/C4 -> 0.13411551 | E23: =(E4-D4)/D4 -> 0.028146711 | F23: =(F4-E4)/E4 -> 0.06597068 | G23: =(G4-F4)/F4 -> 0.057303605 | H23: 0.08 | I23: 0.06 | J23: 0.05 | K23: 0.04 | L23: 0.03
B24: Other U.S. government agencies* | D24: =(D5-C5)/C5 -> 0.13411551 | E24: =(E5-D5)/D5 -> 0.028146711 | F24: =(F5-E5)/E5 -> 0.087512291 | G24: =(G5-F5)/F5 -> -0.043851718 | H24: 0.04 | I24: 0.03 | J24: 0.02 | K24: 0.02 | L24: 0.02
B25: Commercial and non-U.S. customers | D25: =(D6-C6)/C6 -> 0.13411551 | E25: =(E6-D6)/D6 -> 0.028146711 | F25: =(F6-E6)/E6 -> -0.20606061 | G25: =(G6-F6)/F6 -> -0.1221374 | H25: -0.02 | I25: 0 | J25: 0.02 | K25: 0.03 | L25: 0.03
B26: Health & Civil | D26: =(D7-C7)/C7 -> -0.036913465 | E26: =(E7-D7)/D7 -> 0.24453076 | F26: =(F7-E7)/E7 -> 0.073856376 | G26: =(G7-F7)/F7 -> 0.18848168 | H26: =(H7-G7)/G7 -> 0.13723668 | I26: =(I7-H7)/H7 -> 0.11650181 | J26: =(J7-I7)/I7 -> 0.10032021 | K26: =(K7-J7)/J7 -> 0.085229989 | L26: =(L7-K7)/K7 -> 0.060861724
B27: DoD and U.S. Intelligence Community | D27: =(D8-C8)/C8 -> -0.036913465 | E27: =(E8-D8)/D8 -> 0.24453076 | F27: =(F8-E8)/E8 -> 0.011461318 | G27: =(G8-F8)/F8 -> -0.025495751 | H27: 0.02 | I27: 0.02 | J27: 0.01 | K27: 0.01 | L27: 0.01
B28: Other U.S. government agencies* | D28: =(D9-C9)/C9 -> -0.036913465 | E28: =(E9-D9)/D9 -> 0.24453076 | F28: =(F9-E9)/E9 -> 0.099536211 | G28: =(G9-F9)/F9 -> 0.26508761 | H28: 0.17 | I28: 0.14 | J28: 0.12 | K28: 0.1 | L28: 0.07
B29: Commercial and non-U.S. customers | D29: =(D10-C10)/C10 -> -0.036913465 | E29: =(E10-D10)/D10 -> 0.24453076 | F29: =(F10-E10)/E10 -> -0.031746032 | G29: =(G10-F10)/F10 -> 0.032786885 | H29: 0.03 | I29: 0.03 | J29: 0.02 | K29: 0.02 | L29: 0.02
B30: Commercial & International | D30: =(D11-C11)/C11 -> 0.43597404 | E30: =(E11-D11)/D11 -> -0.050044837 | F30: =(F11-E11)/E11 -> 0.12793177 | G30: =(G11-F11)/F11 -> 0.062381853 | H30: =(H11-G11)/G11 -> 0.10141014 | I30: =(I11-H11)/H11 -> 0.088497841 | J30: =(J11-I11)/I11 -> 0.069031472 | K30: =(K11-J11)/J11 -> 0.055741911 | L30: =(L11-K11)/K11 -> 0.038012676
B31: DoD and U.S. Intelligence Community | D31: =(D12-C12)/C12 -> 0.43597404 | E31: =(E12-D12)/D12 -> -0.050044837 | F31: =(F12-E12)/E12 -> -0.14634146 | G31: =(G12-F12)/F12 -> 0.25714286 | H31: 0.07 | I31: 0.06 | J31: 0.05 | K31: 0.05 | L31: 0.04
B32: Other U.S. government agencies* | D32: =(D13-C13)/C13 -> 0.43597404 | E32: =(E13-D13)/D13 -> -0.050044837 | F32: =(F13-E13)/E13 -> 0.13523132 | G32: =(G13-F13)/F13 -> 0.18808777 | H32: 0.16 | I32: 0.13 | J32: 0.11 | K32: 0.08 | L32: 0.07
B33: Commercial and non-U.S. customers | D33: =(D14-C14)/C14 -> 0.43597404 | E33: =(E14-D14)/D14 -> -0.050044837 | F33: =(F14-E14)/E14 -> 0.13384813 | G33: =(G14-F14)/F14 -> 0.035754824 | H33: 0.09 | I33: 0.08 | J33: 0.06 | K33: 0.05 | L33: 0.03
B34: Defense Solutions | D34: =(D15-C15)/C15 -> 0.094018259 | E34: =(E15-D15)/D15 -> -0.08758603 | F34: =(F15-E15)/E15 -> 0.039845047 | G34: =(G15-F15)/F15 -> 0.080361895 | H34: =(H15-G15)/G15 -> 0.063172414 | I34: =(I15-H15)/H15 -> 0.056056277 | J34: =(J15-I15)/I15 -> 0.047464783 | K34: =(K15-J15)/J15 -> 0.048297873 | L34: =(L15-K15)/K15 -> 0.038693015
B35: DoD and U.S. Intelligence Community | D35: =(D16-C16)/C16 -> 0.094018259 | E35: =(E16-D16)/D16 -> -0.08758603 | F35: =(F16-E16)/E16 -> 0.10065359 | G35: =(G16-F16)/F16 -> 0.076009501 | H35: 0.07 | I35: 0.06 | J35: 0.05 | K35: 0.05 | L35: 0.04
B36: Other U.S. government agencies* | D36: =(D17-C17)/C17 -> 0.094018259 | E36: =(E17-D17)/D17 -> -0.08758603 | F36: =(F17-E17)/E17 -> -0.0081967213 | G36: =(G17-F17)/F17 -> -0.21487603 | H36: -0.05 | I36: -0.02 | J36: 0 | K36: 0.02 | L36: 0.02
B37: Commercial and non-U.S. customers | D37: =(D18-C18)/C18 -> 0.094018259 | E37: =(E18-D18)/D18 -> -0.08758603 | F37: =(F18-E18)/E18 -> -0.52258065 | G37: =(G18-F18)/F18 -> 0.66216216 | H37: 0.05 | I37: 0.05 | J37: 0.04 | K37: 0.04 | L37: 0.03
B42: Total Revenue | C42: ='Income Statement Historical'!C5 -> 12297 | D42: ='Income Statement Historical'!D5 -> 13737 | E42: ='Income Statement Historical'!E5 -> 14396 | F42: ='Income Statement Historical'!F5 -> 15438 | G42: ='Income Statement Historical'!G5 -> 16662 | H42: ='Income Statement Historical'!H5 -> 18105.79 | I42: ='Income Statement Historical'!I5 -> 19502.33 | J42: ='Income Statement Historical'!J5 -> 20770.692 | ... L42: ='Income Statement Historical'!L5 -> 22849.177
B43: % National Security & Digital | C43: =C3/C42 -> 0.46733474 | D43: =D3/D42 -> 0.47445238 | E43: =E3/E42 -> 0.46547652 | F43: =F3/F42 -> 0.46262469 | G43: =G3/G42 -> 0.43836274 | H43: =H3/H42 -> 0.43037172 | I43: =I3/I42 -> 0.41979616 | J43: =J3/J42 -> 0.41043431 | ... L43: =L3/L42 -> 0.39649679
B44: % Health & Civil | C44: =C7/C42 -> 0.26548484 | D44: =D7/D42 -> 0.22888236 | E44: =E7/E42 -> 0.27181161 | F44: =F7/F42 -> 0.27218552 | G44: =G7/G42 -> 0.29972392 | H44: =H7/H42 -> 0.31367645 | I44: =I7/I42 -> 0.32514145 | J44: =J7/J42 -> 0.33591311 | ... L44: =L7/L42 -> 0.35155067
B45: % Commercial & International | C45: =C11/C42 -> 0.1118366 | D45: =D11/D42 -> 0.14375992 | E45: =E11/E42 -> 0.13031398 | F45: =F11/F42 -> 0.13706439 | G45: =G11/G42 -> 0.13491778 | H45: =H11/H42 -> 0.13675018 | I45: =I11/I42 -> 0.13819313 | J45: =J11/J42 -> 0.1387115 | ... L45: =L11/L42 -> 0.13818258
...

Sheet Revenue Mapping of old segments
AD5: Revenue Build - USD ($) in millions
AE6: 2020E** | AF6: 2021E**
AC7: 1 | AD7: National Security & Digital | AE7: =SUM(AE8:AE10) -> 5746.8153 | AF7: =SUM(AF8:AF10) -> 6517.5523
AD8: DoD and U.S. Intelligence Community | AE8: =AF31 -> 3860.9405 | AF8: =AK31 -> 4378.7525
AD9: Other U.S. government agencies* | AE9: =AF32 -> 1744.3698 | AF9: =AK32 -> 1978.3169
F10: percent of total rev | G10: percent of group | N10: percent of total rev | O10: percent of group | AD10: Commercial and non-U.S. customers | AE10: =AF33 -> 141.50493 | AF10: =AK33 -> 160.48293
E11: 2022 | F11: 2022 | I11: 2020 | J11: 2021 | M11: 2022 | N11: 2022 | AC11: 2 | AD11: Health & Civil | AE11: =SUM(AE12:AE14) -> 3264.6671 | AF11: =SUM(AF12:AF14) -> 3144.1569
B12: OLD SEGMENT | L12: NEW SEGMENT | Q12: FY22 Revenue Mapping: Old → New Segments (Exact + % of Total) | AD12: DoD and U.S. Intelligence Community | AE12: =AF35 -> 873.5258 | AF12: =AK35 -> 841.28094
B13: Defense Solutions | E13: =SUM(E14:E16) -> 8242 | F13: =E13/$E$26 -> 0.57688808 | I13: =SUM(I14:I16) -> 7339 | J13: =SUM(J14:J16) -> 8029 | L13: National Security & Digital | M13: =SUM(M14:M16) -> 6701 | N13: =M13/$M$30 -> 0.46869973 | AD13: Other U.S. government agencies* | AE13: =AF36 -> 2338.5796 | AF13: =AK36 -> 2252.2545
B14: DoD and U.S. Intelligence Community | E14: 6027 | F14: =E14/$E$26 -> 0.42185203 | G14: =E14/E13 -> 0.73125455 | I14: 5407 | J14: 5939 | L14: DoD and U.S. Intelligence Community | M14: 4502 | N14: =M14/$M$30 -> 0.31489124 | O14: =M14/M13 -> 0.67184002 | Q14: Old Segment | R14: Old Rev ($M) | S14: NS&D ($M) | T14: % | U14: Health & Civil ($M) | V14: % | W14: C&I ($M) | X14: % | Y14: Defense Systems ($M) | Z14: % | AD14: Commercial and non-U.S. customers | AE14: =AF37 -> 52.561724 | AF14: =AK37 -> 50.621489
B15: Other U.S. government agencies* | E15: 1004 | F15: =E15/$E$26 -> 0.070273675 | G15: =E15/E13 -> 0.12181509 | I15: 995 | J15: 964 | L15: Other U.S. government agencies* | M15: 2034 | N15: =M15/$M$30 -> 0.14226761 | O15: =M15/M13 -> 0.30353679 | Q15: Defense | R15: 8242 | S15: 5895 | T15: 0.41 | U15: 0 | V15: 0 | W15: 314 | X15: 0.02 | Y15: 2033 | Z15: 0.14 | AC15: 3 | AD15: Commercial & International | AE15: =SUM(AE16:AE18) -> 1375.2547 | AF15: =SUM(AF16:AF18) -> 1974.83
B16: Commercial and non-U.S. customers | E16: 1211 | F16: =E16/$E$26 -> 0.084762371 | G16: =E16/E13 -> 0.14693036 | I16: 937 | J16: 1126 | L16: Commercial and non-U.S. customers | M16: 165 | N16: =M16/$M$30 -> 0.011540883 | O16: =M16/M13 -> 0.024623191 | Q16: Civil | R16: 3362 | S16: 0 | T16: 0 | U16: 3299 | V16: 0.23 | W16: 63 | X16: 0 | Y16: 0 | Z16: 0 | AD16: DoD and U.S. Intelligence Community | AE16: =AF39 -> 30.056206 | AF16: =AK39 -> 43.159932
B17: Health | E17: =SUM(E18:E20) -> 2683 | F17: =E17/$E$26 -> 0.1877931 | I17: =SUM(I18:I20) -> 2903 | J17: =SUM(J18:J20) -> 3044 | L17: Health & Civil | M17: =SUM(M18:M20) -> 3913 | N17: =M17/$M$30 -> 0.27369378 | Q17: Health | R17: 2683 | S17: 683 | T17: 0.06 | U17: 571 | V17: 0.04 | W17: 1429 | X17: 0.1 | Y17: 0 | Z17: 0 | AD17: Other U.S. government agencies* | AE17: =AF40 -> 205.99497 | AF17: =AK40 -> 295.80343
B18: DoD and U.S. Intelligence Community | E18: 999 | F18: =E18/$E$26 -> 0.069923707 | G18: =E18/E17 -> 0.37234439 | I18: 59 | J18: 54 | L18: DoD and U.S. Intelligence Community | M18: 1047 | N18: =M18/$M$30 -> 0.073232147 | O18: =M18/M17 -> 0.26756964 | Q18: Total | R18: 14287 | S18: 6701 | T18: 0.47 | U18: 3913 | V18: 0.27 | W18: 1876 | X18: 0.13 | Y18: 2033 | Z18: 0.13 | AD18: Commercial and non-U.S. customers | AE18: =AF41 -> 1139.2035 | AF18: =AK41 -> 1635.8667
B19: Other U.S. government agencies* | E19: 1576 | F19: =E19/$E$26 -> 0.11031007 | G19: =E19/E17 -> 0.58740216 | I19: 2418 | J19: 2447 | L19: Other U.S. government agencies* | M19: 2803 | N19: =M19/$M$30 -> 0.19605512 | O19: =M19/M17 -> 0.71633018 | R19: =SUM(S18,U18,W18,Y18) -> 14523 | AC19: 4 | AD19: Defense Solutions | AE19: =SUM(AE20:AE22) -> 1810.2629 | AF19: =SUM(AF20:AF22) -> 1980.4607
B20: Commercial and non-U.S. customers | E20: 108 | F20: =E20/$E$26 -> 0.0075593197 | G20: =E20/E17 -> 0.040253448 | I20: 426 | J20: 543 | L20: Commercial and non-U.S. customers | M20: 63 | N20: =M20/$M$30 -> 0.0044065189 | O20: =M20/M17 -> 0.016100179 | Q20: MAPPING KEY | AD20: DoD and U.S. Intelligence Community | AE20: =AF43 -> 1532.7627 | AF20: =AK43 -> 1676.8704
B21: Civil | E21: =SUM(E22:E24) -> 3362 | F21: =E21/$E$26 -> 0.23531882 | I21: =SUM(I22:I24) -> 1955 | J21: =SUM(J22:J24) -> 2544 | L21: Commercial & International | M21: =SUM(M22:M24) -> 1876 | N21: =M21/$M$30 -> 0.13121634 | R21: NS&D | S21: H&C | T21: C&I | U21: Def Sys | AD21: Other U.S. government agencies* | AE21: =AF44 -> 122.2203 | AF21: =AK44 -> 133.71124
B22: DoD and U.S. Intelligence Community | E22: 84 | F22: =E22/$E$26 -> 0.0058794708 | G22: =E22/E21 -> 0.024985128 | I22: 519 | J22: 756 | L22: DoD and U.S. Intelligence Community | M22: 41 | N22: =M22/$M$30 -> 0.0028677345 | O22: =M22/M21 -> 0.021855011 | Q22: Defense | R22: =S15/R15 -> 0.71523902 | S22: =U15/R15 -> 0 | T22: =W15/R15 -> 0.038097549 | U22: =Y15/R15 -> 0.24666343 | AD22: Commercial and non-U.S. customers | AE22: =AF45 -> 155.27989 | AF22: =AK45 -> 169.87903
B23: Other U.S. government agencies* | E23: 2660 | F23: =E23/$E$26 -> 0.18618324 | G23: =E23/E21 -> 0.79119572 | I23: 1329 | J23: 1681 | L23: Other U.S. government agencies* | M23: 281 | N23: =M23/$M$30 -> 0.019654473 | O23: =M23/M21 -> 0.14978678 | Q23: Civil | R23: =S16/R16 -> 0 | S23: =U16/R16 -> 0.98126115 | T23: =W16/R16 -> 0.018738846 | U23: =Y16/R16 -> 0 | AC23: x | AD23: Total Revenues | AE23: =SUM(AE7,AE11,AE15,AE19) -> 12197 | AF23: =SUM(AF7,AF11,AF15,AF19) -> 13617
B24: Commercial and non-U.S. customers | E24: 618 | F24: =E24/$E$26 -> 0.043256107 | G24: =E24/E21 -> 0.18381916 | I24: 107 | J24: 107 | L24: Commercial and non-U.S. customers | M24: 1554 | N24: =M24/$M$30 -> 0.10869413 | O24: =M24/M21 -> 0.82835821 | Q24: Health | R24: =S17/R17 -> 0.25456578 | S24: =U17/R17 -> 0.21282147 | T24: =W17/R17 -> 0.53261275 | U24: =Y17/R17 -> 0
L25: Defense Solutions | M25: =SUM(M26:M28) -> 1807 | N25: =M25/$M$30 -> 0.12639015 | Q25: totals | R25: =S18/R18 -> 0.46902779 | S25: =U18/R18 -> 0.27388535 | T25: =W18/R18 -> 0.13130818 | U25: =Y18/R18 -> 0.14229719
B26: total | E26: =SUM(E21+E17+E13) -> 14287 | L26: DoD and U.S. Intelligence Community | M26: 1530 | N26: =M26/$M$30 -> 0.10701546 | O26: =M26/M25 -> 0.84670725
L27: Other U.S. government agencies* | M27: 122 | N27: =M27/$M$30 -> 0.0085332587 | O27: =M27/M25 -> 0.067515219
L28: Commercial and non-U.S. customers | M28: 155 | N28: =M28/$M$30 -> 0.010841435 | O28: =M28/M25 -> 0.085777532 | Q28: Mapping percent final of total rev | V28: EXAMPLE MAPPING OF 2022 | AC28: 2020 | AH28: 2021
R29: Defense | S29: Civil | T29: Health | Y29: totals | Z29: percent of total rev | AC29: Defense | AD29: Civil | AE29: Health | AF29: totals | AH29: Defense | AI29: Civil | AJ29: Health | AK29: totals
L30: total | M30: =SUM(M13+M17+M21+M25) -> 14297 | Q30: National Security & Digital | R30: =R22 -> 0.71523902 | S30: =R23 -> 0 | T30: =R24 -> 0.25456578 | V30: =SUM(V31:V33) -> 5895 | W30: =SUM(W31:W33) -> 0 | X30: =SUM(X31:X33) -> 683 | Y30: =SUM(V30:X30) -> 6578 | Z30: =Y30/$Y$47 -> 0.46041856 | AC30: =SUM(AC31:AC33) -> 5249.1392 | AD30: =SUM(AD31:AD33) -> 0 | AE30: =SUM(AE31:AE33) -> 497.67611 | AF30: =SUM(AC30:AE30) -> 5746.8153 | AH30: =SUM(AH31:AH33) -> 5742.6541 | AI30: =SUM(AI31:AI33) -> 0 | AJ30: =SUM(AJ31:AJ33) -> 774.89825 | AK30: =SUM(AH30:AJ30) -> 6517.5523
Q31: DoD and U.S. Intelligence Community | R31: =R30*O14 -> 0.4805262 | S31: 0 | T31: =$T$30*O14 -> 0.17102748 | V31: =$E$13*R31 -> 3960.4969 | W31: =$E$21*S31 -> 0 | X31: =$E$17*T31 -> 458.86674 | Y31: =SUM(V31:X31) -> 4419.3637 | Z31: =Y31/$Y$47 -> 0.30932762 | AC31: =$I$13*R31 -> 3526.5818 | AD31: =$I$17*S31 -> 0 | AE31: =$I$21*T31 -> 334.35873 | AF31: =SUM(AC31:AE31) -> 3860.9405 | AH31: =$J$13*R31 -> 3858.1449 | AI31: =$J$21*S31 -> 0 | AJ31: =$J$17*T31 -> 520.60766 | AK31: =SUM(AH31:AJ31) -> 4378.7525
Q32: Other U.S. government agencies* | R32: =R30*O15 -> 0.21710135 | S32: 0 | T32: =$T$30*O15 -> 0.07727008 | V32: =$E$13*R32 -> 1789.3494 | W32: =$E$21*S32 -> 0 | X32: =$E$17*T32 -> 207.31562 | Y32: =SUM(V32:X32) -> 1996.665 | Z32: =Y32/$Y$47 -> 0.13975397 | AC32: =$I$13*R32 -> 1593.3068 | AD32: =$I$17*S32 -> 0 | AE32: =$I$21*T32 -> 151.06301 | AF32: =SUM(AC32:AE32) -> 1744.3698 | AH32: =$J$13*R32 -> 1743.1068 | AI32: =$J$21*S32 -> 0 | AJ32: =$J$17*T32 -> 235.21012 | AK32: =SUM(AH32:AJ32) -> 1978.3169
Q33: Commercial and non-U.S. customers | R33: =R30*O16 -> 0.017611467 | S33: 0 | T33: =$T$30*O16 -> 0.0062682218 | V33: =$E$13*R33 -> 145.15371 | W33: =$E$21*S33 -> 0 | X33: =$E$17*T33 -> 16.817639 | Y33: =SUM(V33:X33) -> 161.97135 | Z33: =Y33/$Y$47 -> 0.011336974 | AC33: =$I$13*R33 -> 129.25055 | AD33: =$I$17*S33 -> 0 | AE33: =$I$21*T33 -> 12.254374 | AF33: =SUM(AC33:AE33) -> 141.50493 | AH33: =$J$13*R33 -> 141.40247 | AI33: =$J$21*S33 -> 0 | AJ33: =$J$17*T33 -> 19.080467 | AK33: =SUM(AH33:AJ33) -> 160.48293
Q34: Health & Civil | R34: =S22 -> 0 | S34: =S23 -> 0.98126115 | T34: =S24 -> 0.21282147 | V34: =SUM(V35:V37) -> 0 | W34: =SUM(W35:W37) -> 3299 | X34: =SUM(X35:X37) -> 571 | Y34: =SUM(V34:X34) -> 3870 | Z34: =Y34/$Y$47 -> 0.27087562 | AC34: =SUM(AC35:AC37) -> 0 | AD34: =SUM(AD35:AD37) -> 2848.6011 | AE34: =SUM(AE35:AE37) -> 416.06597 | AF34: =SUM(AC34:AE34) -> 3264.6671 | AH34: =SUM(AH35:AH37) -> 0 | AI34: =SUM(AI35:AI37) -> 2496.3284 | AJ34: =SUM(AJ35:AJ37) -> 647.82855 | AK34: =SUM(AK35:AK37) -> 3144.1569
Q35: DoD and U.S. Intelligence Community | R35: 0 | S35: =$S$34*O18 -> 0.26255569 | T35: =$T$34*O18 -> 0.056944564 | V35: =$E$13*R35 -> 0 | W35: =$E$21*S35 -> 882.71224 | X35: =$E$17*T35 -> 152.78226 | Y35: =SUM(V35:X35) -> 1035.4945 | Z35: =Y35/$Y$47 -> 0.072478092 | AC35: =$I$13*R35 -> 0 | AD35: =$I$17*S35 -> 762.19918 | AE35: =$I$21*T35 -> 111.32662 | AF35: =SUM(AC35:AE35) -> 873.5258 | AH35: =$J$13*R35 -> 0 | AI35: =$J$21*S35 -> 667.94168 | AJ35: =$J$17*T35 -> 173.33925 | AK35: =SUM(AH35:AJ35) -> 841.28094
Q36: Other U.S. government agencies* | R36: 0 | S36: =$S$34*O19 -> 0.70290698 | T36: =$T$34*O19 -> 0.15245044 | V36: =$E$13*R36 -> 0 | W36: =$E$21*S36 -> 2363.1733 | X36: =$E$17*T36 -> 409.02453 | Y36: =SUM(V36:X36) -> 2772.1978 | Z36: =Y36/$Y$47 -> 0.19403638 | AC36: =$I$13*R36 -> 0 | AD36: =$I$17*S36 -> 2040.539 | AE36: =$I$21*T36 -> 298.04061 | AF36: =SUM(AC36:AE36) -> 2338.5796 | AH36: =$J$13*R36 -> 0 | AI36: =$J$21*S36 -> 1788.1954 | AJ36: =$J$17*T36 -> 464.05914 | AK36: =SUM(AH36:AJ36) -> 2252.2545
Q37: Commercial and non-U.S. customers | R37: 0 | S37: =$S$34*O20 -> 0.01579848 | T37: =$T$34*O20 -> 0.0034264637 | V37: =$E$13*R37 -> 0 | W37: =$E$21*S37 -> 53.11449 | X37: =$E$17*T37 -> 9.1932021 | Y37: =SUM(V37:X37) -> 62.307692 | Z37: =Y37/$Y$47 -> 0.004361146 | AC37: =$I$13*R37 -> 0 | AD37: =$I$17*S37 -> 45.862988 | AE37: =$I$21*T37 -> 6.6987366 | AF37: =SUM(AC37:AE37) -> 52.561724 | AH37: =$J$13*R37 -> 0 | AI37: =$J$21*S37 -> 40.191333 | AJ37: =$J$17*T37 -> 10.430156 | AK37: =SUM(AH37:AJ37) -> 50.621489
Q38: Commercial & International | R38: =T22 -> 0.038097549 | S38: =T23 -> 0.018738846 | T38: =T24 -> 0.53261275 | V38: =SUM(V39:V41) -> 314 | W38: =SUM(W39:W41) -> 63 | X38: =SUM(X39:X41) -> 1429 | Y38: =SUM(V38:X38) -> 1806 | Z38: =Y38/$Y$47 -> 0.12640862 | AC38: =SUM(AC39:AC41) -> 279.59791 | AD38: =SUM(AD39:AD41) -> 54.39887 | AE38: =SUM(AE39:AE41) -> 1041.2579 | AF38: =SUM(AC38:AE38) -> 1375.2547 | AH38: =SUM(AH39:AH41) -> 305.88522 | AI38: =SUM(AI39:AI41) -> 47.671624 | AJ38: =SUM(AJ39:AJ41) -> 1621.2732 | AK38: =SUM(AH38:AJ38) -> 1974.83
Q39: DoD and U.S. Intelligence Community | R39: =$R$38*O22 -> 0.00083262234 | S39: =$S$38*O22 -> 0.00040953768 | T39: =$T$38*O22 -> 0.011640257 | V39: =$E$13*R39 -> 6.8624733 | W39: =$E$21*S39 -> 1.3768657 | X39: =$E$17*T39 -> 31.23081 | Y39: =SUM(V39:X39) -> 39.470149 | Z39: =Y39/$Y$47 -> 0.0027626618 | AC39: =$I$13*R39 -> 6.1106154 | AD39: =$I$17*S39 -> 1.1888879 | AE39: =$I$21*T39 -> 22.756703 | AF39: =SUM(AC39:AE39) -> 30.056206 | AH39: =$J$13*R39 -> 6.6851248 | AI39: =$J$21*S39 -> 1.0418639 | AJ39: =$J$17*T39 -> 35.432943 | AK39: =SUM(AH39:AJ39) -> 43.159932
Q40: Other U.S. government agencies* | R40: =$R$38*O23 -> 0.0057065092 | S40: =$S$38*O23 -> 0.0028068314 | T40: =$T$38*O23 -> 0.079778349 | V40: =$E$13*R40 -> 47.033049 | W40: =$E$21*S40 -> 9.4365672 | X40: =$E$17*T40 -> 214.04531 | Y40: =SUM(V40:X40) -> 270.51493 | Z40: =Y40/$Y$47 -> 0.018934341 | AC40: =$I$13*R40 -> 41.880071 | AD40: =$I$17*S40 -> 8.1482316 | AE40: =$I$21*T40 -> 155.96667 | AF40: =SUM(AC40:AE40) -> 205.99497 | AH40: =$J$13*R40 -> 45.817563 | AI40: =$J$21*S40 -> 7.1405791 | AJ40: =$J$17*T40 -> 242.84529 | AK40: =SUM(AH40:AJ40) -> 295.80343
Q41: Commercial and non-U.S. customers | R41: =$R$38*O24 -> 0.031558418 | S41: =$S$38*O24 -> 0.015522477 | T41: =$T$38*O24 -> 0.44119414 | V41: =$E$13*R41 -> 260.10448 | W41: =$E$21*S41 -> 52.186567 | X41: =$E$17*T41 -> 1183.7239 | Y41: =SUM(V41:X41) -> 1496.0149 | Z41: =Y41/$Y$47 -> 0.10471162 | AC41: =$I$13*R41 -> 231.60723 | AD41: =$I$17*S41 -> 45.06175 | AE41: =$I$21*T41 -> 862.53455 | AF41: =SUM(AC41:AE41) -> 1139.2035 | AH41: =$J$13*R41 -> 253.38253 | AI41: =$J$21*S41 -> 39.489181 | AJ41: =$J$17*T41 -> 1342.995 | AK41: =SUM(AH41:AJ41) -> 1635.8667
Q42: Defense Solutions | R42: =U22 -> 0.24666343 | S42: =U23 -> 0 | T42: =U24 -> 0 | V42: =SUM(V43:V45) -> 2033 | W42: =SUM(W43:W45) -> 0 | X42: =SUM(X43:X45) -> 0 | Y42: =SUM(V42:X42) -> 2033 | Z42: =Y42/$Y$47 -> 0.14229719 | AC42: =SUM(AC43:AC45) -> 1810.2629 | AD42: =SUM(AD43:AD45) -> 0 | AE42: =SUM(AE43:AE45) -> 0 | AF42: =SUM(AC42:AE42) -> 1810.2629 | AH42: =SUM(AH43:AH45) -> 1980.4607 | AI42: =SUM(AI43:AI45) -> 0 | AJ42: =SUM(AJ43:AJ45) -> 0 | AK42: =SUM(AH42:AJ42) -> 1980.4607
Q43: DoD and U.S. Intelligence Community | R43: =$R$42*O26 -> 0.20885172 | S43: 0 | T43: 0 | V43: =$E$13*R43 -> 1721.3558 | W43: =$E$21*S43 -> 0 | X43: =$E$17*T43 -> 0 | Y43: =SUM(V43:X43) -> 1721.3558 | Z43: =Y43/$Y$47 -> 0.12048407 | AC43: =$I$13*R43 -> 1532.7627 | AD43: =$I$17*S43 -> 0 | AE43: =$I$21*T43 -> 0 | AF43: =SUM(AC43:AE43) -> 1532.7627 | AH43: =$J$13*R43 -> 1676.8704 | AI43: =$J$13*S43 -> 0 | AJ43: =$J$17*T43 -> 0 | AK43: =SUM(AH43:AJ43) -> 1676.8704
Q44: Other U.S. government agencies* | R44: =$R$42*O27 -> 0.016653535 | S44: 0 | T44: 0 | V44: =$E$13*R44 -> 137.25844 | W44: =$E$21*S44 -> 0 | X44: =$E$17*T44 -> 0 | Y44: =SUM(V44:X44) -> 137.25844 | Z44: =Y44/$Y$47 -> 0.0096072261 | AC44: =$I$13*R44 -> 122.2203 | AD44: =$I$17*S44 -> 0 | AE44: =$I$21*T44 -> 0 | AF44: =SUM(AC44:AE44) -> 122.2203 | AH44: =$J$13*R44 -> 133.71124 | AI44: =$J$13*S44 -> 0 | AJ44: =$J$17*T44 -> 0 | AK44: =SUM(AH44:AJ44) -> 133.71124
...

Sheet Balance Sheet Build
A1: x | B1: Balance Sheet Build - USD ($) in millions | C1: Actual | H1: Expected
C2: 2020 | D2: =C2+1 -> 2021 | E2: =D2+1 -> 2022 | F2: =E2+1 -> 2023 | G2: =F2+1 -> 2024 | H2: =G2+1 -> 2025 | I2: =H2+1 -> 2026 | J2: =I2+1 -> 2027 | K2: =J2+1 -> 2028 | L2: =K2+1 -> 2029
B3: Assets
B5: Receivables, net - % of revenue | C5: ='Balance Sheet'!C7/'Income Statement Historical'!C5 -> 0.17378222 | D5: ='Balance Sheet'!D7/'Income Statement Historical'!D5 -> 0.15935066 | E5: ='Balance Sheet'!E7/'Income Statement Historical'!E5 -> 0.16323979 | F5: ='Balance Sheet'!F7/'Income Statement Historical'!F5 -> 0.15733903 | G5: ='Balance Sheet'!G7/'Income Statement Historical'!G5 -> 0.15874445 | H5: =AVERAGE(C5:G5) -> 0.16249123 | I5: =H5 -> 0.16249123 | J5: =I5 -> 0.16249123 | K5: =J5 -> 0.16249123 | L5: =K5 -> 0.16249123
B7: Inventories - % of revenue | C7: ='Balance Sheet'!C8/'Income Statement Historical'!C5 -> 0.022444499 | D7: ='Balance Sheet'!D8/'Income Statement Historical'!D5 -> 0.019946131 | E7: ='Balance Sheet'!E8/'Income Statement Historical'!E5 -> 0.019936093 | F7: ='Balance Sheet'!F8/'Income Statement Historical'!F5 -> 0.020080321 | G7: ='Balance Sheet'!G8/'Income Statement Historical'!G5 -> 0.018905293 | H7: =AVERAGE(C7:G7) -> 0.020262468 | I7: =H7 -> 0.020262468 | J7: =I7 -> 0.020262468 | K7: =J7 -> 0.020262468 | L7: =K7 -> 0.020262468
B9: Other current assets - % of revenue | C9: ='Balance Sheet'!C9/'Income Statement Historical'!C5 -> 0.0326909 | D9: ='Balance Sheet'!D9/'Income Statement Historical'!D5 -> 0.031229526 | E9: ='Balance Sheet'!E9/'Income Statement Historical'!E5 -> 0.034037233 | F9: ='Balance Sheet'!F9/'Income Statement Historical'!F5 -> 0.031675087 | G9: ='Balance Sheet'!G9/'Income Statement Historical'!G5 -> 0.031508822 | H9: =AVERAGE(C9:G9) -> 0.032228314 | I9: =H9 -> 0.032228314 | J9: =I9 -> 0.032228314 | K9: =J9 -> 0.032228314 | L9: =K9 -> 0.032228314
B11: Operating lease right-of-use assets - % of revenue | C11: ='Balance Sheet'!C16/'Income Statement Historical'!C5 -> 0.047247296 | D11: ='Balance Sheet'!D16/'Income Statement Historical'!D5 -> 0.044551212 | E11: ='Balance Sheet'!E16/'Income Statement Historical'!E5 -> 0.037857738 | F11: ='Balance Sheet'!F16/'Income Statement Historical'!F5 -> 0.033164918 | G11: ='Balance Sheet'!G16/'Income Statement Historical'!G5 -> 0.033609411 | H11: =AVERAGE(E11:G11) -> 0.034877356 | I11: =H11 -> 0.034877356 | J11: =I11 -> 0.034877356 | K11: =J11 -> 0.034877356 | L11: =K11 -> 0.034877356
B13: Other long-term assets - % of revenue | C13: ='Balance Sheet'!C17/'Income Statement Historical'!C5 -> 0.037244856 | D13: ='Balance Sheet'!D17/'Income Statement Historical'!D5 -> 0.031957487 | E13: ='Balance Sheet'!E17/'Income Statement Historical'!E5 -> 0.026951931 | F13: ='Balance Sheet'!F17/'Income Statement Historical'!F5 -> 0.028371551 | G13: ='Balance Sheet'!G17/'Income Statement Historical'!G5 -> 0.031448806 | H13: =AVERAGE(C13:G13) -> 0.031194926 | I13: =H13 -> 0.031194926 | J13: =I13 -> 0.031194926 | K13: =J13 -> 0.031194926 | L13: =K13 -> 0.031194926
B15: Intangible Assets - % of revenue | C15: ='Balance Sheet'!C14/'Income Statement Historical'!C5 -> 0.098885907 | D15: ='Balance Sheet'!D14/'Income Statement Historical'!D5 -> 0.085681007 | E15: ='Balance Sheet'!E14/'Income Statement Historical'!E5 -> 0.06612948 | F15: ='Balance Sheet'!F14/'Income Statement Historical'!F5 -> 0.043205078 | G15: ='Balance Sheet'!G14/'Income Statement Historical'!G5 -> 0.031028688 | H15: =G15*$H$16+G15 -> 0.023347431 | I15: =H15*$H$16+H15 -> 0.017567695 | J15: =I15*$H$16+I15 -> 0.013218753 | K15: =J15*$H$16+J15 -> 0.0099464058 | L15: =K15*$H$16+K15 -> 0.0074841393
D16: =(D15-C15)/C15 -> -0.13353672 | E16: =(E15-D15)/D15 -> -0.22818974 | F16: =(F15-E15)/E15 -> -0.34665934 | G16: =(G15-F15)/F15 -> -0.28182776 | H16: =AVERAGE(D16:G16) -> -0.24755339
A17: x | B17: PPE | P17: cap ex
B18: BOY PPE | F18: 0 | G18: =F41 -> 961 | H18: =G41 -> 991 | I18: =H41 -> 1101.9403 | J18: =I41 -> 1186.2048 | K18: =J41 -> 1263.7404 | L18: =K41 -> 1334.3679 | O18: 2024-23 acc dep | P18: end y ppe -beginning + dep
B19: Plus: CapEx | F19: 0 | G19: =G21-G18+G20 -> 121 | H19: =H21-H18+H20 -> 149.58481 | I19: =I21-I18+I20 -> 141.43628 | J19: =J21-J18+J20 -> 130.14197 | K19: =K21-K18+K20 -> 118.54679 | L19: =L21-L18+L20 -> 93.534471
B20: Less: Depreciation Expense | F20: 0 | G20: =G39-F39 -> 91 | H20: =H39-G39 -> 38.644515 | I20: =I39-H39 -> 57.171781 | J20: =J39-I39 -> 52.606362 | K20: =K39-J39 -> 47.919327 | L20: =L39-K39 -> 37.808774
A21: x | B21: EOY PPE | F21: =F41 -> 961 | G21: =G41 -> 991 | H21: =H41 -> 1101.9403 | I21: =I41 -> 1186.2048 | J21: =J41 -> 1263.7404 | K21: =K41 -> 1334.3679 | L21: =L41 -> 1390.0936
B23: Computers and other equipment | F23: 455 | G23: 473 | H23: ='Income Statement Historical'!H5*'Balance Sheet Build'!H24 -> 523.80664 | I23: ='Income Statement Historical'!I5*'Balance Sheet Build'!I24 -> 558.92008 | J23: ='Income Statement Historical'!J5*'Balance Sheet Build'!J24 -> 598.08671 | K23: ='Income Statement Historical'!K5*'Balance Sheet Build'!K24 -> 630.12243 | L23: ='Income Statement Historical'!L5*'Balance Sheet Build'!L24 -> 657.16156
B24: Computers and other equipment - % of revenue | F24: =F23/'Income Statement Historical'!F5 -> 0.02947273 | G24: =G23/'Income Statement Historical'!G5 -> 0.028387949 | H24: =AVERAGE(F24:G24) -> 0.028930339 | I24: =AVERAGE(G24:H24) -> 0.028659144 | J24: =AVERAGE(H24:I24) -> 0.028794742 | K24: =AVERAGE(I24:J24) -> 0.028726943 | L24: =AVERAGE(J24:K24) -> 0.028760842
B25: leasehold improvements | F25: 455 | G25: 567 | H25: ='Income Statement Historical'!H5*H26 -> 574.87927 | I25: ='Income Statement Historical'!I5*I26 -> 641.43804 | J25: ='Income Statement Historical'!J5*J26 -> 671.3239 | K25: ='Income Statement Historical'!K5*K26 -> 715.1988 | L25: ='Income Statement Historical'!L5*L26 -> 741.75577
B26: leasehold improvements - % of revenue | F26: =F25/'Income Statement Historical'!F5 -> 0.02947273 | G26: =G25/'Income Statement Historical'!G5 -> 0.034029528 | H26: =AVERAGE(F26:G26) -> 0.031751129 | I26: =AVERAGE(G26:H26) -> 0.032890329 | J26: =AVERAGE(H26:I26) -> 0.032320729 | K26: =AVERAGE(I26:J26) -> 0.032605529 | L26: =AVERAGE(J26:K26) -> 0.032463129
B27: vehicles and transportation equipment | F27: 277 | G27: 321 | H27: ='Income Statement Historical'!H5*H28 -> 336.84132 | I27: ='Income Statement Historical'!I5*I28 -> 369.27136 | J27: ='Income Statement Historical'!J5*J28 -> 389.8534 | K27: ='Income Statement Historical'!K5*K28 -> 413.51802 | L27: ='Income Statement Historical'!L5*L28 -> 429.80973
B28: vehicles and transportation equipment - % of revenue | F28: =F27/'Income Statement Historical'!F5 -> 0.017942739 | G28: =G27/'Income Statement Historical'!G5 -> 0.019265394 | H28: =AVERAGE(F28:G28) -> 0.018604067 | I28: =AVERAGE(G28:H28) -> 0.01893473 | J28: =AVERAGE(H28:I28) -> 0.018769398 | K28: =AVERAGE(I28:J28) -> 0.018852064 | L28: =AVERAGE(J28:K28) -> 0.018810731
B29: Buildings and improvements | F29: 137 | G29: 137 | H29: ='Income Statement Historical'!H5*H30 -> 154.7729 | I29: ='Income Statement Historical'!I5*I30 -> 163.53246 | J29: ='Income Statement Historical'!J5*J30 -> 175.8606 | K29: ='Income Statement Historical'!K5*K30 -> 184.8239 | L29: ='Income Statement Historical'!L5*L30 -> 192.99316
B30: Buildings and improvements - % of revenue | F30: =F29/'Income Statement Historical'!F5 -> 0.0088742065 | G30: =G29/'Income Statement Historical'!G5 -> 0.0082223022 | H30: =AVERAGE(F30:G30) -> 0.0085482544 | I30: =AVERAGE(G30:H30) -> 0.0083852783 | J30: =AVERAGE(H30:I30) -> 0.0084667663 | K30: =AVERAGE(I30:J30) -> 0.0084260223 | L30: =AVERAGE(J30:K30) -> 0.0084463943
B31: office furniture and fixtures | F31: 66 | G31: 78 | H31: ='Income Statement Historical'!H5*H32 -> 81.082036 | I31: ='Income Statement Historical'!I5*I32 -> 89.31627 | J31: ='Income Statement Historical'!J5*J32 -> 94.070592 | K31: ='Income Statement Historical'!K5*K32 -> 99.900065 | L31: ='Income Statement Historical'!L5*L32 -> 103.77407
B32: office furniture and fixtures - % of revenue | F32: =F31/'Income Statement Historical'!F5 -> 0.0042751652 | G32: =G31/'Income Statement Historical'!G5 -> 0.0046813108 | H32: =AVERAGE(F32:G32) -> 0.004478238 | I32: =AVERAGE(G32:H32) -> 0.0045797744 | J32: =AVERAGE(H32:I32) -> 0.0045290062 | K32: =AVERAGE(I32:J32) -> 0.0045543903 | L32: =AVERAGE(J32:K32) -> 0.0045416982
B33: land | F33: 17 | G33: 17 | H33: ='Income Statement Historical'!H5*H34 -> 19.205396 | I33: ='Income Statement Historical'!I5*I34 -> 20.292349 | J33: ='Income Statement Historical'!J5*J34 -> 21.822118 | K33: ='Income Statement Historical'!K5*K34 -> 22.934353 | L33: ='Income Statement Historical'!L5*L34 -> 23.948056
B34: land - % of revenue | F34: =F33/'Income Statement Historical'!F5 -> 0.0011011789 | G34: =G33/'Income Statement Historical'!G5 -> 0.0010202857 | H34: =AVERAGE(F34:G34) -> 0.0010607323 | I34: =AVERAGE(G34:H34) -> 0.001040509 | J34: =AVERAGE(H34:I34) -> 0.0010506206 | K34: =AVERAGE(I34:J34) -> 0.0010455648 | L34: =AVERAGE(J34:K34) -> 0.0010480927
B35: Construction in progress | F35: 172 | G35: 107 | H35: ='Income Statement Historical'!H5*H36 -> 158.99724 | I35: ='Income Statement Historical'!I5*I36 -> 148.25054 | J35: ='Income Statement Historical'!J5*J36 -> 170.14574 | K35: ='Income Statement Historical'!K5*K36 -> 173.21228 | L35: ='Income Statement Historical'!L5*L36 -> 183.80199
B36: Construction in progress - % of revenue | F36: =F35/'Income Statement Historical'!F5 -> 0.01114134 | G36: =G35/'Income Statement Historical'!G5 -> 0.0064217981 | H36: =AVERAGE(F36:G36) -> 0.0087815688 | I36: =AVERAGE(G36:H36) -> 0.0076016835 | J36: =AVERAGE(H36:I36) -> 0.0081916261 | K36: =AVERAGE(I36:J36) -> 0.0078966548 | L36: =AVERAGE(J36:K36) -> 0.0080441405
B37: Total PPE Gross | F37: =SUM(F23,F25,F27,F29,F31,F33,F35) -> 1579 | G37: =SUM(G23,G25,G27,G29,G31,G33,G35) -> 1700 | H37: =SUM(H23,H25,H27,H29,H31,H33,H35) -> 1849.5848 | I37: =SUM(I23,I25,I27,I29,I31,I33,I35) -> 1991.0211 | J37: =SUM(J23,J25,J27,J29,J31,J33,J35) -> 2121.1631 | K37: =SUM(K23,K25,K27,K29,K31,K33,K35) -> 2239.7098 | L37: =SUM(L23,L25,L27,L29,L31,L33,L35) -> 2333.2443
B39: Accumulated depreciation | F39: 618 | G39: 709 | H39: =H37*H40 -> 747.64452 | I39: =I37*I40 -> 804.8163 | J39: =J37*J40 -> 857.42266 | K39: =K37*K40 -> 905.34199 | L39: =L37*L40 -> 943.15076
B40: % of gross PPE | F40: =F39/F37 -> 0.39138695 | G40: =G39/G37 -> 0.41705882 | H40: =AVERAGE(F40:G40) -> 0.40422289 | I40: =H40 -> 0.40422289 | J40: =I40 -> 0.40422289 | K40: =J40 -> 0.40422289 | L40: =K40 -> 0.40422289
B41: Total PPE, net | F41: =F37-F39 -> 961 | G41: =G37-G39 -> 991 | H41: =H37-H39 -> 1101.9403 | I41: =I37-I39 -> 1186.2048 | J41: =J37-J39 -> 1263.7404 | K41: =K37-K39 -> 1334.3679 | L41: =L37-L39 -> 1390.0936
A43: x | B43: Liabilties
B44: Accounts Payable - % of OpEx | C44: ='Balance Sheet'!C23/'Income Statement Historical'!C15 -> 0.064695991 | D44: ='Balance Sheet'!D23/'Income Statement Historical'!D15 -> 0.054986095 | E44: ='Balance Sheet'!E23/'Income Statement Historical'!E15 -> 0.055079651 | F44: ='Balance Sheet'!F23/'Income Statement Historical'!F15 -> 0.049672673 | G44: ='Balance Sheet'!G23/'Income Statement Historical'!G15 -> 0.04752275 | H44: =AVERAGE(E44:G44) -> 0.050758358 | I44: =H44 -> 0.050758358 | J44: =I44 -> 0.050758358 | K44: =J44 -> 0.050758358 | L44: =K44 -> 0.050758358
B46: Accrued Liabilities - % of OpEx | C46: ='Balance Sheet'!C24/'Income Statement Historical'!C15 -> 0.0831047 | D46: ='Balance Sheet'!D24/'Income Statement Historical'!D15 -> 0.083671037 | E46: ='Balance Sheet'!E24/'Income Statement Historical'!E15 -> 0.058010219 | F46: ='Balance Sheet'!F24/'Income Statement Historical'!F15 -> 0.055746777 | G46: ='Balance Sheet'!G24/'Income Statement Historical'!G15 -> 0.059521402 | H46: =AVERAGE(E46:G46) -> 0.057759466 | I46: =H46 -> 0.057759466 | J46: =I46 -> 0.057759466 | K46: =J46 -> 0.057759466 | L46: =K46 -> 0.057759466
B48: accrued payroll and employee benefits - % of OpEx | C48: ='Balance Sheet'!C27/'Income Statement Historical'!C15 -> 0.055934153 | D48: ='Balance Sheet'!D27/'Income Statement Historical'!D15 -> 0.048073103 | E48: ='Balance Sheet'!E27/'Income Statement Historical'!E15 -> 0.052675083 | F48: ='Balance Sheet'!F27/'Income Statement Historical'!F15 -> 0.046905581 | G48: ='Balance Sheet'!G27/'Income Statement Historical'!G15 -> 0.054668015 | H48: =AVERAGE(C48:G48) -> 0.051651187 | I48: =H48 -> 0.051651187 | J48: =I48 -> 0.051651187 | K48: =J48 -> 0.051651187 | L48: =K48 -> 0.051651187
B50: deferred revenues - % of revenue | C50: ='Balance Sheet'!C25/'Income Statement Historical'!C5 -> 0.039115231 | D50: ='Balance Sheet'!D25/'Income Statement Historical'!D5 -> 0.02649778 | E50: ='Balance Sheet'!E25/'Income Statement Historical'!E5 -> 0.026396221 | F50: ='Balance Sheet'!F25/'Income Statement Historical'!F5 -> 0.028630652 | G50: ='Balance Sheet'!G25/'Income Statement Historical'!G5 -> 0.019985596 | H50: =AVERAGE(C50:G50) -> 0.028125096 | I50: =H50 -> 0.028125096 | J50: =I50 -> 0.028125096 | K50: =J50 -> 0.028125096 | L50: =K50 -> 0.028125096
B52: current portion of long term debt - % of debt | C52: ='Balance Sheet'!C28/('Balance Sheet'!C32+'Balance Sheet'!C28) -> 0.021079258 | D52: ='Balance Sheet'!D28/('Balance Sheet'!D32+'Balance Sheet'!D28) -> 0.095153664 | E52: ='Balance Sheet'!E28/('Balance Sheet'!E32+'Balance Sheet'!E28) -> 0.20162602 | F52: ='Balance Sheet'!F28/('Balance Sheet'!F32+'Balance Sheet'!F28) -> 0.0038445109 | G52: ='Balance Sheet'!G28/('Balance Sheet'!G32+'Balance Sheet'!G28) -> 0.13233405 | H52: =G52 -> 0.13233405 | I52: =H52 -> 0.13233405 | J52: =I52 -> 0.13233405 | K52: =J52 -> 0.13233405 | L52: =K52 -> 0.13233405
