Workbook

Sheet Cover
B12: Ticker | C12: HQY
B13: Date | C13: 46004
B14: Current Price | C14: 96.79
B15: Implied Price | C15: 160.60018
B16: Premium (Discount) | C16: 0.6592642
B17: Cost of Equity | C17: 0.050558
B18: Recommendation | C18: BUY

Sheet quarterly IS
B1: Income Statement- USD($) and shares in thousands | C1: Actual
C2: 2020A | D2: 2021 Q1 | E2: 2021 Q2 | F2: 2021 Q3 | G2: 2021 Q4 | H2: 2021A | I2: 2022 Q1 | J2: 2022 Q2 | K2: 2022 Q3 | L2: 2022 Q4 | M2: 2022A | N2: 2023 Q1 | O2: 2023 Q2 | P2: 2023 Q3 | Q2: 2023 Q4 | R2: 2023A | S2: 2024 Q1 | T2: 2024 Q2 | U2: 2024 Q3 | V2: 2024 Q4 | W2: 2024A | X2: 2025Q1 | Y2: 2025Q2 | Z2: 2025Q3
B3: REVENUE
B4: Service Revenue | C4: 430966 | D4: 102534 | E4: 109182 | F4: 102733 | G4: ='annual IS'!D5-SUM('quarterly IS'!D4:F4) -> 112461 | H4: =SUM(D4:G4) -> 426910 | I4: 104348 | J4: 103034 | K4: 108580 | L4: ='annual IS'!E5-SUM('quarterly IS'!I4:K4) -> 136064 | M4: =SUM(I4:L4) -> 452026 | N4: 111073 | O4: 111960 | P4: 114082 | Q4: ='annual IS'!F5-SUM('quarterly IS'!N4:P4) -> 118575 | R4: =SUM(N4:Q4) -> 455690 | S4: 118214 | T4: 116720 | U4: 119174 | V4: ='annual IS'!G5-SUM('quarterly IS'!S4:U4) -> 124209 | W4: =SUM(S4:V4) -> 478317 | X4: 119785 | Y4: 117873 | Z4: 120286
B5: Custodial Revenue | C5: 190933 | D5: 46978 | E5: 48776 | F5: 49006 | G5: ='annual IS'!D6-SUM('quarterly IS'!D5:F5) -> 58057 | H5: =SUM(D5:G5) -> 202817 | I5: 59365 | J5: 65599 | K5: 74642 | L5: ='annual IS'!E6-SUM('quarterly IS'!I5:K5) -> 61676 | M5: =SUM(I5:L5) -> 261282 | N5: 88480 | O5: 92676 | P5: 100005 | Q5: ='annual IS'!F6-SUM('quarterly IS'!N5:P5) -> 105433 | R5: =SUM(N5:Q5) -> 386594 | S5: 121644 | T5: 138684 | U5: 140953 | V5: ='annual IS'!G6-SUM('quarterly IS'!S5:U5) -> 144133 | W5: =SUM(S5:V5) -> 545414 | X5: 156455 | Y5: 159876 | Z5: 159067
B6: Interchange Revenue | C6: 111671 | D6: 34690 | E6: 31145 | F6: 28215 | G6: ='annual IS'!D7-SUM('quarterly IS'!D6:F6) -> 32779 | H6: =SUM(D6:G6) -> 126829 | I6: 41966 | J6: 37509 | K6: 32864 | L6: ='annual IS'!E7-SUM('quarterly IS'!I6:K6) -> 36101 | M6: =SUM(I6:L6) -> 148440 | N6: 44879 | O6: 38913 | P6: 35132 | Q6: ='annual IS'!F7-SUM('quarterly IS'!N6:P6) -> 38379 | R6: =SUM(N6:Q6) -> 157303 | S6: 47739 | T6: 44524 | U6: 40305 | V6: ='annual IS'!G7-SUM('quarterly IS'!S6:U6) -> 43475 | W6: =SUM(S6:V6) -> 176043 | X6: 54605 | Y6: 48086 | Z6: 42811
A7: x | B7: Total revenue | C7: 733570 | D7: =SUM(D4:D6) -> 184202 | E7: =SUM(E4:E6) -> 189103 | F7: =SUM(F4:F6) -> 179954 | G7: =SUM(G4:G6) -> 203297 | H7: =SUM(H4:H6) -> 756556 | I7: =SUM(I4:I6) -> 205679 | J7: =SUM(J4:J6) -> 206142 | K7: =SUM(K4:K6) -> 216086 | ... Z7: =SUM(Z4:Z6) -> 322164
B8: Revenue Growth (Q/Q) | E8: =(E7-D7)/D7 -> 0.02660666 | F8: =(F7-E7)/E7 -> -0.048381041 | G8: =(G7-F7)/F7 -> 0.12971648 | H8: =(H7-C7)/C7 -> 0.031334433 | I8: =(I7-D7)/D7 -> 0.11659483 | J8: =(J7-E7)/E7 -> 0.090104335 | K8: =(K7-F7)/F7 -> 0.20078464 | L8: =(L7-G7)/G7 -> 0.15024324 | M8: =(M7-H7)/H7 -> 0.1390406 | N8: =(N7-I7)/I7 -> 0.18841496 | O8: =(O7-J7)/J7 -> 0.18146229 | ... W8: =(W7-R7)/R7 -> 0.20026971 | X8: =(X7-V7)/V7 -> 0.061022972 | Y8: =(Y7-X7)/X7 -> -0.015143043 | Z8: =(Z7-Y7)/Y7 -> -0.011266439
B10: COGS
B11: Service Costs | C11: 280214 | D11: 70632 | E11: 67334 | F11: 66217 | G11: ='annual IS'!D12-SUM('quarterly IS'!D11:F11) -> 86119 | H11: =SUM(D11:G11) -> 290302 | I11: 80874 | J11: 74914 | K11: 76493 | L11: ='annual IS'!E12-SUM('quarterly IS'!I11:K11) -> 86235 | M11: =SUM(I11:L11) -> 318516 | N11: 80873 | O11: 76904 | P11: 75721 | Q11: ='annual IS'!F12-SUM('quarterly IS'!N11:P11) -> 83859 | R11: =SUM(N11:Q11) -> 317357 | S11: 82347 | T11: 76915 | U11: 86860 | V11: ='annual IS'!G12-SUM('quarterly IS'!S11:U11) -> 105466 | W11: =SUM(S11:V11) -> 351588 | X11: 88005 | Y11: 75156 | Z11: 76889
B12: Custodial Costs | C12: 19574 | D12: 5009 | E12: 4824 | F12: 5734 | G12: ='annual IS'!D13-SUM('quarterly IS'!D12:F12) -> 6300 | H12: =SUM(D12:G12) -> 21867 | I12: 6641 | J12: 7090 | K12: 6812 | L12: ='annual IS'!E13-SUM('quarterly IS'!I12:K12) -> 5558 | M12: =SUM(I12:L12) -> 26101 | N12: 8038 | O12: 8037 | P12: 8029 | Q12: ='annual IS'!F13-SUM('quarterly IS'!N12:P12) -> 8398 | R12: =SUM(N12:Q12) -> 32502 | S12: 9057 | T12: 10108 | U12: 10241 | V12: ='annual IS'!G13-SUM('quarterly IS'!S12:U12) -> 10269 | W12: =SUM(S12:V12) -> 39675 | X12: 10747 | Y12: 11137 | Z12: 10879
B13: Interchange Costs | C13: 18448 | D13: 5445 | E13: 4974 | F13: 4683 | G13: ='annual IS'!D14-SUM('quarterly IS'!D13:F13) -> 5579 | H13: =SUM(D13:G13) -> 20681 | I13: 6991 | J13: 6326 | K13: 5923 | L13: ='annual IS'!E14-SUM('quarterly IS'!I13:K13) -> 5956 | M13: =SUM(I13:L13) -> 25196 | N13: 7051 | O13: 6943 | P13: 6287 | Q13: ='annual IS'!F14-SUM('quarterly IS'!N13:P13) -> 6810 | R13: =SUM(N13:Q13) -> 27091 | S13: 9055 | T13: 8853 | U13: 6305 | V13: ='annual IS'!G14-SUM('quarterly IS'!S13:U13) -> 7039 | W13: =SUM(S13:V13) -> 31252 | X13: 7781 | Y13: 6947 | Z13: 6333
B14: Total COGS | C14: =SUM(C11:C13) -> 318236 | D14: =SUM(D11:D13) -> 81086 | E14: =SUM(E11:E13) -> 77132 | F14: =SUM(F11:F13) -> 76634 | G14: =SUM(G11:G13) -> 97998 | H14: =SUM(H11:H13) -> 332850 | I14: =SUM(I11:I13) -> 94506 | J14: =SUM(J11:J13) -> 88330 | ... Z14: =SUM(Z11:Z13) -> 94101
A15: x | B15: Gross profit | C15: =C7-C14 -> 415334 | D15: =D7-D14 -> 103116 | E15: =E7-E14 -> 111971 | F15: =F7-F14 -> 103320 | G15: =G7-G14 -> 105299 | H15: =H7-H14 -> 423706 | I15: =I7-I14 -> 111173 | J15: =J7-J14 -> 117812 | ... Z15: =Z7-Z14 -> 228063
B16: Gross profit margin | C16: =C15/C7 -> 0.56618182 | D16: =D15/D7 -> 0.55979848 | E16: =E15/E7 -> 0.59211647 | F16: =F15/F7 -> 0.57414673 | G16: =G15/G7 -> 0.51795649 | H16: =H15/H7 -> 0.56004579 | I16: =I15/I7 -> 0.54051702 | J16: =J15/J7 -> 0.57150896 | ... Z16: =Z15/Z7 -> 0.70790964
B17: Gross profit margin growth | E17: =(E16-D16)/D16 -> 0.05773146 | F17: =(F16-E16)/E16 -> -0.030348319 | G17: =(G16-F16)/F16 -> -0.097867386 | H17: =(H16-C16)/C16 -> -0.010837573 | I17: =(I16-D16)/D16 -> -0.034443578 | J17: =(J16-E16)/E16 -> -0.034803129 | K17: =(K16-F16)/F16 -> 0.02251182 | L17: =(L16-G16)/G16 -> 0.12361793 | M17: =(M16-H16)/H16 -> 0.019304413 | N17: =(N16-I16)/I16 -> 0.12375406 | O17: =(O16-J16)/J16 -> 0.089622281 | ... W17: =(W16-R16)/R16 -> 0.040044658 | X17: =(X16-V16)/V16 -> 0.11832265 | Y17: =(Y16-X16)/X16 -> 0.0528699 | Z17: =(Z16-Y16)/Y16 -> -0.0083117166
B18: OPERATING EXPENSES
B19: Sales and marketing | C19: 49964 | D19: 14086 | E19: 15476 | F19: 12726 | G19: ='annual IS'!D20-SUM('quarterly IS'!D19:F19) -> 16317 | H19: =SUM(D19:G19) -> 58605 | I19: 16560 | J19: 15843 | K19: 17245 | L19: ='annual IS'!E20-SUM('quarterly IS'!I19:K19) -> 19201 | M19: =SUM(I19:L19) -> 68849 | N19: 19935 | O19: 19123 | P19: 19656 | Q19: ='annual IS'!F20-SUM('quarterly IS'!N19:P19) -> 20559 | R19: =SUM(N19:Q19) -> 79273 | S19: 23494 | T19: 21525 | U19: 22636 | V19: ='annual IS'!G20-SUM('quarterly IS'!S19:U19) -> 23084 | W19: =SUM(S19:V19) -> 90739 | X19: 25984 | Y19: 19922 | Z19: 24411
B20: Technology and development | C20: 124809 | D20: 35469 | E20: 37898 | F20: 38070 | G20: ='annual IS'!D21-SUM('quarterly IS'!D20:F20) -> 45927 | H20: =SUM(D20:G20) -> 157364 | I20: 45183 | J20: 46580 | K20: 48890 | L20: ='annual IS'!E21-SUM('quarterly IS'!I20:K20) -> 52722 | M20: =SUM(I20:L20) -> 193375 | N20: 53192 | O20: 54767 | P20: 55614 | Q20: ='annual IS'!F21-SUM('quarterly IS'!N20:P20) -> 55238 | R20: =SUM(N20:Q20) -> 218811 | S20: 56090 | T20: 58580 | U20: 60189 | V20: ='annual IS'!G21-SUM('quarterly IS'!S20:U20) -> 64654 | W20: =SUM(S20:V20) -> 239513 | X20: 61436 | Y20: 64804 | Z20: 65916
B21: General and administrative | C21: 84493 | D21: 20687 | E21: 22812 | F21: 20004 | G21: ='annual IS'!D22-SUM('quarterly IS'!D21:F21) -> 20876 | H21: =SUM(D21:G21) -> 84379 | I21: 23727 | J21: 25937 | K21: 25131 | L21: ='annual IS'!E22-SUM('quarterly IS'!I21:K21) -> 22677 | M21: =SUM(I21:L21) -> 97472 | N21: 25538 | O21: 27825 | P21: 27153 | Q21: ='annual IS'!F22-SUM('quarterly IS'!N21:P21) -> 23140 | R21: =SUM(N21:Q21) -> 103656 | S21: 38236 | T21: 32260 | U21: 31789 | V21: ='annual IS'!G22-SUM('quarterly IS'!S21:U21) -> 29975 | W21: =SUM(S21:V21) -> 132260 | X21: 25536 | Y21: 29990 | Z21: 30880
B22: Amortization of acquired intangible assets | C22: 76064 | D22: 19814 | E22: 20289 | F22: 19642 | G22: ='annual IS'!D23-SUM('quarterly IS'!D22:F22) -> 23046 | H22: =SUM(D22:G22) -> 82791 | I22: 23698 | J22: 24181 | K22: 23541 | L22: ='annual IS'!E23-SUM('quarterly IS'!I22:K22) -> 23166 | M22: =SUM(I22:L22) -> 94586 | N22: 23166 | O22: 23166 | P22: 23213 | Q22: ='annual IS'!F23-SUM('quarterly IS'!N22:P22) -> 23218 | R22: =SUM(N22:Q22) -> 92763 | S22: 25545 | T22: 30981 | U22: 28350 | V22: ='annual IS'!G23-SUM('quarterly IS'!S22:U22) -> 27002 | W22: =SUM(S22:V22) -> 111878 | X22: 27002 | Y22: 27001 | Z22: 27002
B23: Merger Integration | C23: 45990 | D23: 8807 | E23: 16371 | F23: 13244 | G23: ='annual IS'!D24-SUM('quarterly IS'!D23:F23) -> 26383 | H23: =SUM(D23:G23) -> 64805 | I23: 9294 | J23: 7683 | K23: 6509 | L23: ='annual IS'!E24-SUM('quarterly IS'!I23:K23) -> 5110 | M23: =SUM(I23:L23) -> 28596 | N23: 3458 | O23: 2044 | P23: 2655 | Q23: ='annual IS'!F24-SUM('quarterly IS'!N23:P23) -> 2278 | R23: =SUM(N23:Q23) -> 10435 | S23: 2143 | T23: 1777 | U23: 34437 | V23: ='annual IS'!G24-SUM('quarterly IS'!S23:U23) -> 2178 | W23: =SUM(S23:V23) -> 40535 | X23: 1275 | Y23: 1266 | Z23: 1159
B24: Total Operating Expense | C24: =SUM(C19:C23) -> 381320 | D24: =SUM(D19:D23) -> 98863 | E24: =SUM(E19:E23) -> 112846 | F24: =SUM(F19:F23) -> 103686 | G24: =SUM(G19:G23) -> 132549 | H24: =SUM(H19:H23) -> 447944 | I24: =SUM(I19:I23) -> 118462 | J24: =SUM(J19:J23) -> 120224 | ... Z24: =SUM(Z19:Z23) -> 149368
B25: OpEx Growth | E25: =(E24-D24)/D24 -> 0.14143815 | F25: =(F24-E24)/E24 -> -0.081172571 | G25: =(G24-F24)/F24 -> 0.27836931 | H25: =(H24-C24)/C24 -> 0.1747194 | I25: =(I24-D24)/D24 -> 0.19824403 | J25: =(J24-E24)/E24 -> 0.065381139 | K25: =(K24-F24)/F24 -> 0.1700326 | L25: =(L24-G24)/G24 -> -0.072976786 | M25: =(M24-H24)/H24 -> 0.077987427 | N25: =(N24-I24)/I24 -> 0.057630295 | O25: =(O24-J24)/J24 -> 0.055737623 | ... W25: =(W24-R24)/R24 -> 0.21782278 | X25: =(X24-146893)/146893 -> -0.038531448 | Y25: =(Y24-X24)/X24 -> 0.012390872 | Z25: =(Z24-Y24)/Y24 -> 0.044655658
A26: x | B26: EBIT | C26: =C15-C24 -> 34014 | D26: =D15-D24 -> 4253 | E26: =E15-E24 -> -875 | F26: =F15-F24 -> -366 | G26: =G15-G24 -> -27250 | H26: =H15-H24 -> -24238 | I26: =I15-I24 -> -7289 | J26: =J15-J24 -> -2412 | ... Z26: =Z15-Z24 -> 78695
B27: EBIT Margin | C27: =C26/C7 -> 0.046367763 | D27: =D26/D7 -> 0.023088783 | E27: =E26/E7 -> -0.004627108 | F27: =F26/F7 -> -0.0020338531 | G27: =G26/G7 -> -0.13404034 | H27: =H26/H7 -> -0.032037285 | I27: =I26/I7 -> -0.035438718 | J27: =J26/J7 -> -0.011700672 | ... Z27: =Z26/Z7 -> 0.24427
B29: OTHER INCOME (EXPENSE)
B30: Interest expense | C30: -34881 | D30: -6689 | E30: -7254 | F30: -11881 | G30: ='annual IS'!D31-SUM('quarterly IS'!D30:F30) -> -10748 | H30: =SUM(D30:G30) -> -36572 | I30: -10461 | J30: -11493 | K30: -12165 | L30: ='annual IS'!E31-SUM('quarterly IS'!I30:K30) -> -14305 | M30: =SUM(I30:L30) -> -48424 | N30: -14997 | O30: -13272 | P30: -13545 | Q30: ='annual IS'!F31-SUM('quarterly IS'!N30:P30) -> -13641 | R30: =SUM(N30:Q30) -> -55455 | S30: -11795 | T30: -15427 | U30: -18155 | V30: ='annual IS'!G31-SUM('quarterly IS'!S30:U30) -> -15257 | W30: =SUM(S30:V30) -> -60634 | X30: -14858 | Y30: -14955 | Z30: -14049
B31: Other income, net | C31: 5007 | D31: -3630 | E31: 344 | F31: 3122 | G31: ='annual IS'!D32-SUM('quarterly IS'!D31:F31) -> -5767 | H31: ='annual IS'!D32 -> -5931 | I31: -301 | J31: 32 | K31: 443 | L31: ='annual IS'!E32-SUM('quarterly IS'!I31:K31) -> 1097 | M31: =SUM(I31:L31) -> 1271 | N31: 1828 | O31: 2756 | P31: 3741 | Q31: ='annual IS'!F32-SUM('quarterly IS'!N31:P31) -> 4471 | R31: =SUM(N31:Q31) -> 12796 | S31: 3404 | T31: 3114 | U31: 4748 | V31: ='annual IS'!G32-SUM('quarterly IS'!S31:U31) -> 3068 | W31: =SUM(S31:V31) -> 14334 | X31: 2733 | Y31: 3391 | Z31: 2886
B32: Total other expense | C32: =SUM(C30:C31) -> -29874 | D32: =SUM(D30:D31) -> -10319 | E32: =SUM(E30:E31) -> -6910 | F32: =SUM(F30:F31) -> -8759 | G32: =SUM(G30:G31) -> -16515 | H32: =SUM(H30:H31) -> -42503 | I32: =SUM(I30:I31) -> -10762 | J32: =SUM(J30:J31) -> -11461 | ... Z32: =SUM(Z30:Z31) -> -11163
A33: x | B33: INCOME BEFORE INCOME TAXES (EBT) | C33: =C26+C32 -> 4140 | D33: =D26+D32 -> -6066 | E33: =E26+E32 -> -7785 | F33: =F26+F32 -> -9125 | G33: =G26+G32 -> -43765 | H33: =H26+H32 -> -66741 | I33: =I26+I32 -> -18051 | J33: =J26+J32 -> -13873 | ... Z33: =Z26+Z32 -> 67532
B34: Provision for income taxes (benefit) | C34: -4694 | D34: -3451 | E34: -3967 | F34: -4087 | G34: =SUM('annual IS'!D35-SUM('quarterly IS'!D34:F34)) -> -10947 | H34: -22452 | I34: -4412 | J34: -3219 | K34: -4539 | L34: ='annual IS'!E35-SUM('quarterly IS'!I34:K34) -> 217 | M34: -11953 | N34: 5918 | O34: 3643 | P34: 6414 | Q34: ='annual IS'!F35-SUM('quarterly IS'!N34:P34) -> 3353 | R34: 19328 | S34: 4426 | T34: 10794 | U34: 515 | V34: ='annual IS'!G35-SUM('quarterly IS'!S34:U34) -> 3596 | W34: 19331 | X34: 17038 | Y34: 18194 | Z34: 15840
B35: Effective tax rate | C35: =C34/C33 -> -1.1338164 | D35: =D34/D33 -> 0.56890867 | E35: =E34/E33 -> 0.50956969 | F35: =F34/F33 -> 0.44789041 | G35: =G34/G33 -> 0.25013138 | H35: =H34/H33 -> 0.33640491 | I35: =I34/I33 -> 0.24441859 | J35: =J34/J33 -> 0.23203345 | ... Z35: =Z34/Z33 -> 0.23455547
A37: x | B37: NET INCOME ATTRIBUTABLE TO HQY | C37: =C33-C34 -> 8834 | D37: =D33-D34 -> -2615 | E37: =E33-E34 -> -3818 | F37: =F33-F34 -> -5038 | G37: =G33-G34 -> -32818 | H37: =H33-H34 -> -44289 | I37: =I33-I34 -> -13639 | J37: =J33-J34 -> -10654 | ... Z37: =Z33-Z34 -> 51692
B38: Net Income Margin | C38: =C37/C7 -> 0.012042477 | D38: =D37/D7 -> -0.014196371 | E38: =E37/E7 -> -0.020190055 | F38: =F37/F7 -> -0.027996043 | G38: =G37/G7 -> -0.16142885 | H38: =H37/H7 -> -0.05854028 | I38: =I37/I7 -> -0.066312069 | J38: =J37/J7 -> -0.051682821 | ... Z38: =Z37/Z7 -> 0.16045244
B40: NET INCOME PER COMMON SHARE ATTRIBUTABLE TO HQY:
B41: Basic | C41: 0.12 | D41: -0.03 | E41: -0.05 | F41: -0.06 | G41: =SUM('annual IS'!D42-SUM('quarterly IS'!D41:F41)) -> -0.39 | H41: =SUM(D41:G41) -> -0.53 | I41: -0.16 | J41: -0.13 | K41: -0.02 | L41: ='annual IS'!E42-SUM('quarterly IS'!I41:K41) -> 0 | M41: -0.31 | N41: 0.05 | O41: 0.12 | P41: 0.17 | Q41: ='annual IS'!F42-SUM('quarterly IS'!N41:P41) -> 0.31 | R41: 0.65 | S41: 0.33 | T41: 0.41 | U41: 0.07 | V41: ='annual IS'!G42-SUM('quarterly IS'!S41:U41) -> 0.3 | W41: 1.11 | X41: 0.62 | Y41: 0.69 | Z41: 0.6
B42: Diluted | C42: 0.12 | D42: -0.03 | E42: -0.05 | F42: -0.06 | G42: =SUM('annual IS'!D43-SUM('quarterly IS'!D42:F42)) -> -0.39 | H42: =SUM(D42:G42) -> -0.53 | I42: -0.16 | J42: -0.13 | K42: -0.02 | L42: ='annual IS'!E43-SUM('quarterly IS'!I42:K42) -> 0 | M42: -0.31 | N42: 0.05 | O42: 0.12 | P42: 0.17 | Q42: ='annual IS'!F43-SUM('quarterly IS'!N42:P42) -> 0.3 | R42: 0.64 | S42: 0.33 | T42: 0.4 | U42: 0.06 | V42: ='annual IS'!G43-SUM('quarterly IS'!S42:U42) -> 0.3 | W42: 1.09 | X42: 0.61 | Y42: 0.68 | Z42: 0.59
B44: Shares used in calculation (000’s)
B45: Basic | C45: 74235 | D45: 81747 | E45: 83481 | F45: 83551 | G45: =SUM('annual IS'!D46) -> 83133 | H45: =G45 -> 83133 | I45: 84022 | J45: 84443 | K45: 84572 | L45: ='annual IS'!E46 -> 84442 | M45: =L45 -> 84442 | N45: 85030 | O45: 85533 | P45: 85697 | Q45: ='annual IS'!F46 -> 85564 | R45: =Q45 -> 85564 | S45: 86472 | T45: 87131 | U45: 87193 | V45: ='annual IS'!G46 -> 86870 | W45: =V45 -> 86870 | X45: 86655 | Y45: 86550 | Z45: 85995
...

Sheet annual IS
B2: Income Statement- USD($) and shares in thousands | C2: Actual | H2: Expected
C3: 2020 | D3: =C3+1 -> 2021 | E3: =D3+1 -> 2022 | F3: =E3+1 -> 2023 | G3: =F3+1 -> 2024 | H3: =G3+1 -> 2025 | I3: =H3+1 -> 2026 | J3: =I3+1 -> 2027 | K3: =J3+1 -> 2028 | L3: =K3+1 -> 2029
B4: REVENUE
B5: Service Revenue | C5: 430966 | D5: 426910 | E5: 452026 | F5: 455690 | G5: 478317 | H5: ='Revenue Build'!X3 -> 491352.42 | I5: ='Revenue Build'!Y3 -> 505600.02 | J5: ='Revenue Build'!Z3 -> 522131.77 | K5: ='Revenue Build'!AA3 -> 539980.28 | L5: ='Revenue Build'!AB3 -> 559558.64
B6: Custodial Revenue | C6: 190933 | D6: 202817 | E6: 261282 | F6: 386594 | G6: 545414 | H6: ='Revenue Build'!X4 -> 662102.22 | I6: ='Revenue Build'!Y4 -> 750965.44 | J6: ='Revenue Build'!Z4 -> 838801.15 | K6: ='Revenue Build'!AA4 -> 893208.91 | L6: ='Revenue Build'!AB4 -> 951582.23
B7: Interchange Revenue | C7: 111671 | D7: 126829 | E7: 148440 | F7: 157303 | G7: 176043 | H7: ='Revenue Build'!X5 -> 185908.66 | I7: ='Revenue Build'!Y5 -> 196655.06 | J7: ='Revenue Build'!Z5 -> 208765 | K7: ='Revenue Build'!AA5 -> 221933.57 | L7: ='Revenue Build'!AB5 -> 236399.35
A8: x | B8: Total revenue | C8: =SUM(C5:C7) -> 733570 | D8: =SUM(D5:D7) -> 756556 | E8: =SUM(E5:E7) -> 861748 | F8: =SUM(F5:F7) -> 999587 | G8: =SUM(G5:G7) -> 1199774 | H8: =SUM(H5:H7) -> 1339363.3 | I8: =SUM(I5:I7) -> 1453220.5 | J8: =SUM(J5:J7) -> 1569697.9 | ... L8: =SUM(L5:L7) -> 1747540.2
B9: Revenue Growth (Y/Y or Q/Q) | D9: =(D8-C8)/C8 -> 0.031334433 | E9: =(E8-D8)/D8 -> 0.1390406 | F9: =(F8-E8)/E8 -> 0.15995279 | G9: =(G8-F8)/F8 -> 0.20026971 | H9: =(H8-G8)/G8 -> 0.11634633 | I9: =(I8-H8)/H8 -> 0.085008475 | J9: =(J8-I8)/I8 -> 0.08015121 | K9: =(K8-J8)/J8 -> 0.054421201 | L9: =(L8-K8)/K8 -> 0.055837225
B11: COGS
B12: Service Costs | C12: 280214 | D12: 290302 | E12: 318516 | F12: 317357 | G12: 351588 | H12: ='Expense Build'!AA5 -> 353773.74 | I12: ='Expense Build'!AB5 -> 369088.02 | J12: ='Expense Build'!AC5 -> 386377.51 | K12: ='Expense Build'!AD5 -> 404985.21 | L12: ='Expense Build'!AE5 -> 425264.57
B13: Custodial Costs | C13: 19574 | D13: 21867 | E13: 26101 | F13: 32502 | G13: 39675 | H13: ='Expense Build'!AA6 -> 48163.24 | I13: ='Expense Build'!AB6 -> 50872.582 | J13: ='Expense Build'!AC6 -> 52628.822 | K13: ='Expense Build'!AD6 -> 51576.479 | L13: ='Expense Build'!AE6 -> 50189.213
B14: Interchange Costs | C14: 18448 | D14: 20681 | E14: 25196 | F14: 27091 | G14: 31252 | H14: ='Expense Build'!AA7 -> 31520.695 | I14: ='Expense Build'!AB7 -> 33342.741 | J14: ='Expense Build'!AC7 -> 35395.973 | K14: ='Expense Build'!AD7 -> 37628.696 | L14: ='Expense Build'!AE7 -> 40081.359
B15: Total COGS | C15: =SUM(C12:C14) -> 318236 | D15: =SUM(D12:D14) -> 332850 | E15: =SUM(E12:E14) -> 369813 | F15: =SUM(F12:F14) -> 376950 | G15: =SUM(G12:G14) -> 422515 | H15: =SUM(H12:H14) -> 433457.68 | I15: =SUM(I12:I14) -> 453303.34 | J15: =SUM(J12:J14) -> 474402.3 | ... L15: =SUM(L12:L14) -> 515535.14
A16: x | B16: Gross profit | C16: =C8-C15 -> 415334 | D16: =D8-D15 -> 423706 | E16: =E8-E15 -> 491935 | F16: =F8-F15 -> 622637 | G16: =G8-G15 -> 777259 | H16: =H8-H15 -> 905905.62 | I16: =I8-I15 -> 999917.19 | J16: =J8-J15 -> 1095295.6 | ... L16: =L8-L15 -> 1232005.1
B17: Gross profit margin | C17: =C16/C8 -> 0.56618182 | D17: =D16/D8 -> 0.56004579 | E17: =E16/E8 -> 0.57085714 | F17: =F16/F8 -> 0.62289426 | G17: =G16/G8 -> 0.64783784 | H17: =H16/H8 -> 0.67637035 | I17: =I16/I8 -> 0.68806982 | J17: =J16/J8 -> 0.69777478 | ... L17: =L16/L8 -> 0.70499383
B19: OPERATING EXPENSES
B20: Sales and marketing | C20: 49964 | D20: 58605 | E20: 68849 | F20: 79273 | G20: 90739 | H20: ='Expense Build'!AA10 -> 101899.84 | I20: ='Expense Build'!AB10 -> 110562.19 | J20: ='Expense Build'!AC10 -> 119423.88 | K20: ='Expense Build'!AD10 -> 125923.07 | L20: ='Expense Build'!AE10 -> 132954.27
B21: Technology and development | C21: 124809 | D21: 157364 | E21: 193375 | F21: 218811 | G21: 239513 | H21: ='Expense Build'!AA11 -> 273517.1 | I21: ='Expense Build'!AB11 -> 296768.37 | J21: ='Expense Build'!AC11 -> 320554.72 | K21: ='Expense Build'!AD11 -> 337999.69 | L21: ='Expense Build'!AE11 -> 356872.66
B22: General and administrative | C22: 84493 | D22: 84379 | E22: 97472 | F22: 103656 | G22: 132260 | H22: ='Expense Build'!AA12 -> 148336.32 | I22: ='Expense Build'!AB12 -> 160946.17 | J22: ='Expense Build'!AC12 -> 173846.19 | K22: ='Expense Build'!AD12 -> 183307.11 | L22: ='Expense Build'!AE12 -> 193542.47
B23: Amortization of acquired intangible assets | C23: 76064 | D23: 82791 | E23: 94586 | F23: 92763 | G23: 111878 | H23: ='Expense Build'!AA13 -> 136329.18 | I23: ='Expense Build'!AB13 -> 147918.31 | J23: ='Expense Build'!AC13 -> 159774.14 | K23: ='Expense Build'!AD13 -> 168469.24 | L23: ='Expense Build'!AE13 -> 177876.1
B24: Merger Integration | C24: 45990 | D24: 64805 | E24: 28596 | F24: 10435 | G24: 40535 | H24: ='Expense Build'!AA14 -> 4710 | I24: ='Expense Build'!AB14 -> 0 | J24: ='Expense Build'!AC14 -> 0 | K24: ='Expense Build'!AD14 -> 0 | L24: ='Expense Build'!AE14 -> 0
B25: Total Operating Expense | C25: =SUM(C20:C24) -> 381320 | D25: =SUM(D20:D24) -> 447944 | E25: =SUM(E20:E24) -> 482878 | F25: =SUM(F20:F24) -> 504938 | G25: =SUM(G20:G24) -> 614925 | H25: =SUM(H20:H24) -> 664792.44 | I25: =SUM(I20:I24) -> 716195.04 | J25: =SUM(J20:J24) -> 773598.94 | ... L25: =SUM(L20:L24) -> 861245.5
B26: OpEx Growth | D26: =(D25-C25)/C25 -> 0.1747194 | E26: =(E25-D25)/D25 -> 0.077987427 | F26: =(F25-E25)/E25 -> 0.045684417 | G26: =(G25-F25)/F25 -> 0.21782278 | H26: =(H25-G25)/G25 -> 0.081095157 | I26: =(I25-H25)/H25 -> 0.077321279 | J26: =(J25-I25)/I25 -> 0.08015121 | K26: =(K25-J25)/J25 -> 0.054421201 | L26: =(L25-K25)/K25 -> 0.055837225
A27: x | B27: EBIT | C27: =C16-C25 -> 34014 | D27: =D16-D25 -> -24238 | E27: =E16-E25 -> 9057 | F27: =F16-F25 -> 117699 | G27: =G16-G25 -> 162334 | H27: =H16-H25 -> 241113.18 | I27: =I16-I25 -> 283722.15 | J27: =J16-J25 -> 321696.67 | ... L27: =L16-L25 -> 370759.58
B28: EBIT Margin | C28: =C27/C8 -> 0.046367763 | D28: =D27/D8 -> -0.032037285 | E28: =E27/E8 -> 0.010510033 | F28: =F27/F8 -> 0.11774763 | G28: =G27/G8 -> 0.13530382 | H28: =H27/H8 -> 0.18002074 | I28: =I27/I8 -> 0.19523681 | J28: =J27/J8 -> 0.20494177 | ... L28: =L27/L8 -> 0.21216083
B30: OTHER INCOME (EXPENSE)
B31: Interest expense | C31: -34881 | D31: -36572 | E31: -48424 | F31: -55455 | G31: -60634 | H31: ='Expense Build'!AA18 -> -57102.601 | I31: ='Expense Build'!AB18 -> -60516.648 | J31: ='Expense Build'!AC18 -> -63811.542 | K31: ='Expense Build'!AD18 -> -65643.997 | L31: ='Expense Build'!AE18 -> -67577.543
B32: Other income, net | C32: 5007 | D32: -5931 | E32: 1271 | F32: 12796 | G32: 14334 | H32: ='Expense Build'!AA41*'annual IS'!H8 -> 5627.4461 | I32: ='Expense Build'!AB41*'annual IS'!I8 -> 6105.8267 | J32: ='Expense Build'!AC41*'annual IS'!J8 -> 6595.2161 | K32: ='Expense Build'!AD41*'annual IS'!K8 -> 6954.1357 | L32: ='Expense Build'!AE41*'annual IS'!L8 -> 7342.4353
B33: Total other expense | C33: =SUM(C31:C32) -> -29874 | D33: =SUM(D31:D32) -> -42503 | E33: =SUM(E31:E32) -> -47153 | F33: =SUM(F31:F32) -> -42659 | G33: =SUM(G31:G32) -> -46300 | H33: =SUM(H31:H32) -> -51475.155 | I33: =SUM(I31:I32) -> -54410.821 | J33: =SUM(J31:J32) -> -57216.326 | ... L33: =SUM(L31:L32) -> -60235.108
A34: x | B34: INCOME BEFORE INCOME TAXES (EBT) | C34: =C27+C33 -> 4140 | D34: =D27+D33 -> -66741 | E34: =E27+E33 -> -38096 | F34: =F27+F33 -> 75040 | G34: =G27+G33 -> 116034 | H34: =H27+H33 -> 189638.02 | I34: =I27+I33 -> 229311.33 | J34: =J27+J33 -> 264480.34 | ... L34: =L27+L33 -> 310524.47
B35: Provision for income taxes (benefit) | C35: -4694 | D35: -22452 | E35: -11953 | F35: 19328 | G35: 19331 | H35: ='Expense Build'!AA39*'annual IS'!H34 -> 45968.257 | I35: ='Expense Build'!AB39*'annual IS'!I34 -> 57006.796 | J35: ='Expense Build'!AC39*'annual IS'!J34 -> 65591.125 | K35: ='Expense Build'!AD39*'annual IS'!K34 -> 71635.847 | L35: ='Expense Build'!AE39*'annual IS'!L34 -> 77631.118
B36: Effective tax rate | C36: =C35/C34 -> -1.1338164 | D36: =D35/D34 -> 0.33640491 | E36: =E35/E34 -> 0.31375997 | F36: =F35/F34 -> 0.2575693 | G36: =G35/G34 -> 0.16659772 | H36: 0.2424 | I36: 0.2486 | J36: 0.248 | K36: 0.25 | L36: 0.25
A38: x | B38: NET INCOME ATTRIBUTABLE TO HQY | C38: =C34-C35 -> 8834 | D38: =D34-D35 -> -44289 | E38: =E34-E35 -> -26143 | F38: =F34-F35 -> 55712 | G38: =G34-G35 -> 96703 | H38: =H34-H35 -> 143669.77 | I38: =I34-I35 -> 172304.53 | J38: =J34-J35 -> 198889.22 | ... L38: =L34-L35 -> 232893.35
B39: Net Income Margin | C39: =C38/C8 -> 0.012042477 | D39: =D38/D8 -> -0.05854028 | E39: =E38/E8 -> -0.030337175 | F39: =F38/F8 -> 0.055735019 | G39: =G38/G8 -> 0.080601013 | H39: =H38/H8 -> 0.10726721 | I39: =I38/I8 -> 0.11856737 | J39: =J38/J8 -> 0.12670541 | ... L39: =L38/L8 -> 0.13326924
B41: NET INCOME PER COMMON SHARE ATTRIBUTABLE TO HQY:
B42: Basic | C42: 0.12 | D42: -0.53 | E42: -0.31 | F42: 0.65 | G42: 1.11 | H42: =H38/H46 -> 1.6538479 | I42: =I38/I46 -> 1.9834757 | J42: =J38/J46 -> 2.2895041 | K42: =K38/K46 -> 2.4738982 | L42: =L38/L46 -> 2.6809411
B43: Diluted | C43: 0.12 | D43: -0.53 | E43: -0.31 | F43: 0.64 | G43: 1.09 | H43: =H38/H47 -> 1.6173928 | I43: =I38/I47 -> 1.9397547 | J43: =J38/J47 -> 2.2390374 | K43: =K38/K47 -> 2.4193671 | L43: =L38/L47 -> 2.6218462
B45: Shares used in calculation (000’s)
B46: Basic | C46: 74235 | D46: 83133 | E46: 84442 | F46: 85564 | G46: 86870 | H46: =G46 -> 86870 | I46: =H46 -> 86870 | J46: =I46 -> 86870 | K46: =J46 -> 86870 | L46: =K46 -> 86870
B47: Diluted | C47: 75679 | D47: 83133 | E47: 84442 | F47: 86957 | G47: 88828 | H47: =G47 -> 88828 | I47: =H47 -> 88828 | J47: =I47 -> 88828 | K47: =J47 -> 88828 | L47: =K47 -> 88828

Sheet Balance Sheet
B1: Balance Sheet - USD($) in thousands | C1: Actual | AA1: Expected
A2: x | C2: 2020A | D2: 2021 Q1 | E2: 2021 Q2 | F2: 2021 Q3 | G2: 2021 Q4 | H2: 2021A | I2: 2022 Q1 | J2: 2022 Q2 | K2: 2022 Q3 | L2: 2022 Q4 | M2: 2022A | N2: 2023 Q1 | O2: 2023 Q2 | P2: 2023 Q3 | Q2: 2023 Q4 | R2: 2023A | S2: 2024 Q1 | T2: 2024 Q2 | U2: 2024 Q3 | V2: 2024 Q4 | W2: 2024A | X2: 2025Q1 | Y2: 2025Q2 | Z2: 2025Q3 | AA2: 2025 | AB2: =AA2+1 -> 2026 | AC2: =AB2+1 -> 2027 | AD2: =AC2+1 -> 2028 | AE2: =AD2+1 -> 2029
B3: Assets
B4: Current assets
B5: Cash and cash equivalents | C5: 328803 | D5: 736773 | E5: 753754 | F5: 649129 | G5: 225414 | H5: =G5 -> 225414 | I5: 161247 | J5: =(176886*(1))*1 -> 176886 | K5: 210197 | L5: 254266 | M5: =L5 -> 254266 | N5: 225642 | O5: 290345 | P5: 334061 | Q5: 403979 | R5: =Q5 -> 403979 | S5: 251229 | T5: 326893 | U5: 322163 | V5: 295948 | W5: =V5 -> 295948 | X5: 287894 | Y5: 304461 | Z5: 309259 | AA5: ='Cash Flow Statement'!C35+W5 -> 751420.15 | AB5: ='Cash Flow Statement'!D35+AA5 -> 1208797.9 | AC5: ='Cash Flow Statement'!E35+AB5 -> 1679022.9 | AD5: ='Cash Flow Statement'!F35+AC5 -> 2127396.4 | AE5: ='Cash Flow Statement'!G35+AD5 -> 2598043.9
B6: Accounts receivable, net | C6: 72767 | D6: 74468 | E6: 74223 | F6: 84083 | G6: 87428 | H6: =G6 -> 87428 | I6: 86003 | J6: =(90426*(1))*1 -> 90426 | K6: 87716 | L6: 96835 | M6: =L6 -> 96835 | N6: 98414 | O6: 92581 | P6: 96181 | Q6: 104893 | R6: =Q6 -> 104893 | S6: 106218 | T6: 108454 | U6: 106712 | V6: 118006 | W6: =V6 -> 118006 | X6: 116256 | Y6: 111164 | Z6: 111243 | AA6: ='Balance Sheet Build'!H5*'annual IS'!H8 -> 142084.98 | AB6: ='Balance Sheet Build'!I5*'annual IS'!I8 -> 154163.41 | AC6: ='Balance Sheet Build'!J5*'annual IS'!J8 -> 166519.79 | AD6: ='Balance Sheet Build'!K5*'annual IS'!K8 -> 175582 | AE6: ='Balance Sheet Build'!L5*'annual IS'!L8 -> 185386.01
B7: Prepaid expenses and Other current assets | C7: 58607 | D7: 53870 | E7: 32637 | F7: 30919 | G7: 38495 | H7: =G7 -> 38495 | I7: 31673 | J7: =(41274*(1))*1 -> 41274 | K7: 34247 | L7: 31792 | M7: =L7 -> 31792 | N7: 34353 | O7: 39631 | P7: 44166 | Q7: 48564 | R7: =Q7 -> 48564 | S7: 47455 | T7: 60280 | U7: 66371 | V7: 63795 | W7: =V7 -> 63795 | X7: 68646 | Y7: 77207 | Z7: 78206 | AA7: ='Balance Sheet Build'!H7*'annual IS'!H8 -> 61900.476 | AB7: ='Balance Sheet Build'!I7*'annual IS'!I8 -> 67162.541 | AC7: ='Balance Sheet Build'!J7*'annual IS'!J8 -> 72545.7 | AD7: ='Balance Sheet Build'!K7*'annual IS'!K8 -> 76493.724 | AE7: ='Balance Sheet Build'!L7*'annual IS'!L8 -> 80764.922
B8: Total current assets | C8: =SUM(C5:C7) -> 460177 | D8: =SUM(D5:D7) -> 865111 | E8: =SUM(E5:E7) -> 860614 | F8: =SUM(F5:F7) -> 764131 | G8: =SUM(G5:G7) -> 351337 | H8: =G8 -> 351337 | I8: =SUM(I5:I7) -> 278923 | J8: =SUM(J5:J7) -> 308586 | K8: =SUM(K5:K7) -> 332160 | L8: =SUM(L5:L7) -> 382893 | M8: =L8 -> 382893 | N8: =SUM(N5:N7) -> 358409 | O8: =SUM(O5:O7) -> 422557 | P8: =SUM(P5:P7) -> 474408 | Q8: =SUM(Q5:Q7) -> 557436 | R8: =Q8 -> 557436 | S8: =SUM(S5:S7) -> 404902 | T8: =SUM(T5:T7) -> 495627 | U8: =SUM(U5:U7) -> 495246 | V8: =SUM(V5:V7) -> 477749 | W8: =V8 -> 477749 | X8: =SUM(X5:X7) -> 472796 | Y8: =SUM(Y5:Y7) -> 492832 | Z8: =SUM(Z5:Z7) -> 498708 | AA8: =SUM(AA5:AA7) -> 955405.61 | AB8: =SUM(AB5:AB7) -> 1430123.8 | AC8: =SUM(AC5:AC7) -> 1918088.3 | AD8: =SUM(AD5:AD7) -> 2379472.1 | AE8: =SUM(AE5:AE7) -> 2864194.8
B9: Property and equipment, net | C9: 29106 | D9: 27479 | E9: 27382 | F9: 24930 | G9: 23372 | H9: =G9 -> 23372 | I9: 21003 | J9: =(18028*(1))*1 -> 18028 | K9: 15620 | L9: 12862 | M9: =L9 -> 12862 | N9: 10532 | O9: 9145 | P9: 7660 | Q9: 6013 | R9: =Q9 -> 6013 | S9: 5083 | T9: 4592 | U9: 3890 | V9: 3239 | W9: =V9 -> 3239 | X9: 3173 | Y9: 3088 | Z9: 3390 | AA9: ='Balance Sheet Build'!H17 -> 1434.7951 | AB9: ='Balance Sheet Build'!I17 -> 567.13293 | AC9: ='Balance Sheet Build'!J17 -> 807.19999 | AD9: ='Balance Sheet Build'!K17 -> 2301.6739 | AE9: ='Balance Sheet Build'!L17 -> 5190.2502
B10: Operating lease right-of-use assets | C10: 89508 | D10: 86139 | E10: 83768 | F10: 81150 | G10: 63613 | H10: =G10 -> 63613 | I10: 62599 | J10: =(60588*(1))*1 -> 60588 | K10: 58536 | L10: 56461 | M10: =L10 -> 56461 | N10: 56726 | O10: 51976 | P10: 50329 | Q10: 48380 | R10: =Q10 -> 48380 | S10: 48108 | T10: 46484 | U10: 44845 | V10: 43185 | W10: =V10 -> 43185 | X10: 41446 | Y10: 39756 | Z10: 38045 | AA10: ='Balance Sheet Build'!H9*'annual IS'!H8 -> 44861.008 | AB10: ='Balance Sheet Build'!I9*'annual IS'!I8 -> 45041.522 | AC10: ='Balance Sheet Build'!J9*'annual IS'!J8 -> 44727.41 | AD10: ='Balance Sheet Build'!K9*'annual IS'!K8 -> 43023.723 | AE10: ='Balance Sheet Build'!L9*'annual IS'!L8 -> 41057.197
B11: Intangible assets, net | C11: 767003 | D11: 780794 | E11: 770329 | F11: 820946 | G11: 973137 | H11: =G11 -> 973137 | I11: 1007864 | J11: =(991945*(1))*1 -> 991945 | K11: 964531 | L11: 936359 | M11: =L11 -> 936359 | N11: 907703 | O11: 881937 | P11: 860514 | Q11: 835948 | R11: =Q11 -> 835948 | S11: 1071371 | T11: 1254210 | U11: 1228476 | V11: 1204658 | W11: =V11 -> 1204658 | X11: 1179430 | Y11: 1152456 | Z11: 1124768 | AA11: ='Balance Sheet Build'!H22 -> 1058149 | AB11: ='Balance Sheet Build'!I22 -> 928548.47 | AC11: ='Balance Sheet Build'!J22 -> 816904.47 | AD11: ='Balance Sheet Build'!K22 -> 718749.47 | AE11: ='Balance Sheet Build'!L22 -> 621619.47
B12: Goodwill | C12: 1327193 | D12: 1363568 | E12: 1363568 | F12: 1363549 | G12: 1645836 | H12: =G12 -> 1645836 | I12: 1645836 | J12: =(1645999*(1))*1 -> 1645999 | K12: 1645759 | L12: 1648145 | M12: =L12 -> 1648145 | N12: 1648145 | O12: 1648145 | P12: 1648145 | Q12: 1648145 | R12: =Q12 -> 1648145 | S12: 1648145 | T12: 1648145 | U12: 1648145 | V12: 1648145 | W12: =V12 -> 1648145 | X12: 1648145 | Y12: 1648145 | Z12: 1648145 | AA12: =W12 -> 1648145 | AB12: =X12 -> 1648145 | AC12: =Y12 -> 1648145 | AD12: =Z12 -> 1648145 | AE12: =AA12 -> 1648145
B13: Other assets | C13: 37420 | D13: 38778 | E13: 42973 | F13: 44908 | G13: 49807 | H13: =G13 -> 49807 | I13: 48842 | J13: =(48878*(1))*1 -> 48878 | K13: 48151 | L13: 52180 | M13: =L13 -> 52180 | N13: 53494 | O13: 52696 | P13: 52446 | Q13: 67868 | R13: =Q13 -> 67868 | S13: 68875 | T13: 65408 | U13: 67745 | V13: 71574 | W13: =V13 -> 71574 | X13: 71283 | Y13: 80401 | Z13: 85005 | AA13: ='Balance Sheet Build'!H11*'annual IS'!H8 -> 93755.431 | AB13: ='Balance Sheet Build'!I11*'annual IS'!I8 -> 103178.66 | AC13: ='Balance Sheet Build'!J11*'annual IS'!J8 -> 113018.25 | AD13: ='Balance Sheet Build'!K11*'annual IS'!K8 -> 120823.96 | AE13: ='Balance Sheet Build'!L11*'annual IS'!L8 -> 129317.98
B14: Total assets, non-current | C14: =SUM(C9:C13) -> 2250230 | D14: =SUM(D9:D13) -> 2296758 | E14: =SUM(E9:E13) -> 2288020 | F14: =SUM(F9:F13) -> 2335483 | G14: =SUM(G9:G13) -> 2755765 | H14: =SUM(H9:H13) -> 2755765 | I14: =SUM(I9:I13) -> 2786144 | J14: =SUM(J9:J13) -> 2765438 | ... AE14: =SUM(AE9:AE13) -> 2445329.9
B15: Total assets | C15: =SUM(C9:C13,C8) -> 2710407 | D15: =SUM(D9:D13,D8) -> 3161869 | E15: =SUM(E9:E13,E8) -> 3148634 | F15: =SUM(F9:F13,F8) -> 3099614 | G15: =SUM(G9:G13,G8) -> 3107102 | H15: =G15 -> 3107102 | I15: =SUM(I9:I13,I8) -> 3065067 | J15: =SUM(J9:J13,J8) -> 3074024 | K15: =SUM(K9:K13,K8) -> 3064757 | L15: =SUM(L9:L13,L8) -> 3088900 | M15: =L15 -> 3088900 | N15: =SUM(N9:N13,N8) -> 3035009 | O15: =SUM(O9:O13,O8) -> 3066456 | P15: =SUM(P9:P13,P8) -> 3093502 | Q15: =SUM(Q9:Q13,Q8) -> 3163790 | R15: =Q15 -> 3163790 | S15: =SUM(S9:S13,S8) -> 3246484 | T15: =SUM(T9:T13,T8) -> 3514466 | U15: =SUM(U9:U13,U8) -> 3488347 | V15: =SUM(V9:V13,V8) -> 3448550 | W15: =V15 -> 3448550 | X15: =W15 -> 3448550 | Y15: =X15 -> 3448550 | Z15: =Y15 -> 3448550 | AA15: =AA14+AA8 -> 3801750.8 | AB15: =AB14+AB8 -> 4155604.6 | AC15: =AC14+AC8 -> 4541690.7 | AD15: =AD14+AD8 -> 4912516 | AE15: =AE14+AE8 -> 5309524.7
B16: Liabilities and stockholders’ equity
B17: Current liabilities
B18: Accounts payable | C18: 1614 | D18: 9636 | E18: 4696 | F18: 5244 | G18: 2 | H18: 27541 | I18: 13661 | J18: =(15841*(1))*1 -> 15841 | K18: 15842 | L18: 13899 | M18: =L18 -> 13899 | N18: 13362 | O18: 12543 | P18: 13419 | Q18: 12041 | R18: =Q18 -> 12041 | S18: 18167 | T18: 10562 | U18: 10352 | V18: 14361 | W18: =V18 -> 14361 | X18: 13496 | Y18: 9600 | Z18: 19549 | AA18: ='Balance Sheet Build'!H32*'annual IS'!H15 -> 14956.662 | AB18: ='Balance Sheet Build'!I32*'annual IS'!I15 -> 15641.445 | AC18: ='Balance Sheet Build'!J32*'annual IS'!J15 -> 16369.475 | AD18: ='Balance Sheet Build'!K32*'annual IS'!K15 -> 17052.272 | AE18: ='Balance Sheet Build'!L32*'annual IS'!L15 -> 17788.783
B19: Accrued compensation | C19: 50670 | D19: 33045 | E19: 40154 | F19: 32695 | G19: -211.46912 | H19: 47136 | I19: 33405 | J19: =(41989*(1))*1 -> 41989 | K19: 35140 | L19: 45835 | M19: =L19 -> 45835 | N19: 20001 | O19: 31421 | P19: 31208 | Q19: 49608 | R19: =Q19 -> 49608 | S19: 23103 | T19: 37072 | U19: 47514 | V19: 69330 | W19: =V19 -> 69330 | X19: 24433 | Y19: 32482 | Z19: 43735 | AA19: ='Balance Sheet Build'!H34*'annual IS'!H25 -> 71628.365 | AB19: ='Balance Sheet Build'!I34*'annual IS'!I25 -> 73585.787 | AC19: ='Balance Sheet Build'!J34*'annual IS'!J25 -> 75615.782 | AD19: ='Balance Sheet Build'!K34*'annual IS'!K25 -> 75652.388 | AE19: ='Balance Sheet Build'!L34*'annual IS'!L25 -> 75570.38
B20: Accrued liabilities | C20: 75880 | D20: 73446 | E20: 49098 | F20: 49879 | G20: 30786.203 | H20: 57589 | I20: 47840 | J20: =(43287*(1))*1 -> 43287 | K20: 33367 | L20: 43668 | M20: =L20 -> 43668 | N20: 45647 | O20: 49281 | P20: 41840 | Q20: 46038 | R20: =Q20 -> 46038 | S20: 41192 | T20: 63379 | U20: 86725 | V20: 62631 | W20: =V20 -> 62631 | X20: 68444 | Y20: 64543 | Z20: 47413 | AA20: ='Balance Sheet Build'!H36*'annual IS'!H25 -> 68477.397 | AB20: ='Balance Sheet Build'!I36*'annual IS'!I25 -> 73772.157 | AC20: ='Balance Sheet Build'!J36*'annual IS'!J25 -> 79685.085 | AD20: ='Balance Sheet Build'!K36*'annual IS'!K25 -> 84021.643 | AE20: ='Balance Sheet Build'!L36*'annual IS'!L25 -> 88713.178
B21: Current portion of long-term debt | C21: 62500 | D21: 62500 | E21: 78125 | F21: 6563 | G21: 80272.687 | H21: 8750 | I21: 10938 | J21: =(13125*(1))*1 -> 13125 | K21: 15313 | L21: 17500 | M21: =L21 -> 17500 | N21: — | O21: — | P21: — | Q21: — | R21: 0 | S21: — | T21: — | U21: — | V21: — | W21: 0 | X21: — | Y21: — | Z21: — | AA21: 0 | AB21: 0 | AC21: 0 | AD21: 0 | AE21: 0
B22: Operating lease liabilities | C22: 14037 | D22: 13677 | E22: 13051 | F22: 12693 | G22: 92850.675 | H22: 12171 | I22: 11807 | J22: =(11275*(1))*1 -> 11275 | K22: 10713 | L22: 10159 | M22: =L22 -> 10159 | N22: 10646 | O22: 10026 | P22: 9769 | Q22: 9404 | R22: =Q22 -> 9404 | S22: 9755 | T22: 9895 | U22: 9948 | V22: 10001 | W22: =V22 -> 10001 | X22: 9969 | Y22: 9950 | Z22: 9931 | AA22: ='Balance Sheet Build'!H38*'annual IS'!H25 -> 15942.878 | AB22: ='Balance Sheet Build'!I38*'annual IS'!I25 -> 17175.602 | AC22: ='Balance Sheet Build'!J38*'annual IS'!J25 -> 18552.247 | AD22: ='Balance Sheet Build'!K38*'annual IS'!K25 -> 19561.883 | AE22: ='Balance Sheet Build'!L38*'annual IS'!L25 -> 20654.164
B23: Total current liabilities | C23: =SUM(C18:C22) -> 204701 | D23: =SUM(D18:D22) -> 192304 | E23: =SUM(E18:E22) -> 185124 | F23: =SUM(F18:F22) -> 107074 | G23: 153187 | H23: =G23 -> 153187 | I23: =SUM(I18:I22) -> 117651 | J23: =SUM(J18:J22) -> 125517 | K23: =SUM(K18:K22) -> 110375 | L23: =SUM(L18:L22) -> 131061 | M23: =L23 -> 131061 | N23: =SUM(N18:N22) -> 89656 | O23: =SUM(O18:O22) -> 103271 | P23: =SUM(P18:P22) -> 96236 | Q23: =SUM(Q18:Q22) -> 117091 | R23: =Q23 -> 117091 | S23: =SUM(S18:S22) -> 92217 | T23: =SUM(T18:T22) -> 120908 | U23: =SUM(U18:U22) -> 154539 | V23: =SUM(V18:V22) -> 156323 | W23: =V23 -> 156323 | X23: =SUM(X18:X22) -> 116342 | Y23: =SUM(Y18:Y22) -> 116575 | Z23: =SUM(Z18:Z22) -> 120628 | AA23: =SUM(AA18:AA22) -> 171005.3 | AB23: =SUM(AB18:AB22) -> 180174.99 | AC23: =SUM(AC18:AC22) -> 190222.59 | AD23: =SUM(AD18:AD22) -> 196288.19 | AE23: =SUM(AE18:AE22) -> 202726.51
B24: Long-term liabilities
B25: Long-term debt, net | C25: 924217 | D25: 909820 | E25: 895449 | F25: 923501 | G25: 922077 | H25: =G25 -> 922077 | I25: 918514 | J25: =(914966*(1))*1 -> 914966 | K25: 911406 | L25: 907838 | M25: =L25 -> 907838 | N25: 872902 | O25: 873581 | P25: 874270 | Q25: 874972 | R25: =Q25 -> 874972 | S25: 925675 | T25: 1101400 | U25: 1081039 | V25: 1056301 | W25: =V25 -> 1056301 | X25: 1056566 | Y25: 1006834 | Z25: 982105 | AA25: ='Balance Sheet Build'!H41*'annual IS'!H8 -> 1152410.5 | AB25: ='Balance Sheet Build'!I41*'annual IS'!I8 -> 1221310.7 | AC25: ='Balance Sheet Build'!J41*'annual IS'!J8 -> 1287806.3 | AD25: ='Balance Sheet Build'!K41*'annual IS'!K8 -> 1324787.8 | AE25: ='Balance Sheet Build'!L41*'annual IS'!L8 -> 1363809.5
B26: Operating lease liabilities, non-current | C26: 74224 | D26: 71916 | E26: 69998 | F26: 67836 | G26: 65232 | H26: =G26 -> 65232 | I26: 64344 | J26: =(62626*(1))*1 -> 62626 | K26: 60819 | L26: 58988 | M26: =L26 -> 58988 | N26: 58625 | O26: 52371 | P26: 50580 | Q26: 48766 | R26: =Q26 -> 48766 | S26: 48253 | T26: 46158 | U26: 44202 | V26: 42219 | W26: =V26 -> 42219 | X26: 40223 | Y26: 38240 | Z26: 36228 | AA26: ='Balance Sheet Build'!H43*'Expense Build'!AA15 -> 45642.756 | AB26: ='Balance Sheet Build'!I43*'Expense Build'!AB15 -> 45590.938 | AC26: ='Balance Sheet Build'!J43*'Expense Build'!AC15 -> 45377.112 | AD26: ='Balance Sheet Build'!K43*'Expense Build'!AD15 -> 43768.093 | AE26: ='Balance Sheet Build'!L43*'Expense Build'!AE15 -> 41905.754
B27: Other long-term liabilities | C27: 8808 | D27: 14811 | E27: 20091 | F27: 18953 | G27: 14185 | H27: =G27 -> 14185 | I27: 13919 | J27: 13731 | K27: 9758 | L27: 12708 | M27: =L27 -> 12708 | N27: 13307 | O27: 13092 | P27: 17711 | Q27: 19270 | R27: =Q27 -> 19270 | S27: 19273 | T27: 25497 | U27: 25275 | V27: 22962 | W27: =V27 -> 22962 | X27: 22178 | Y27: 21993 | Z27: 23501 | AA27: ='Balance Sheet Build'!H45*'annual IS'!H8 -> 22479.822 | AB27: ='Balance Sheet Build'!I45*'annual IS'!I8 -> 24390.798 | AC27: ='Balance Sheet Build'!J45*'annual IS'!J8 -> 26345.75 | AD27: ='Balance Sheet Build'!K45*'annual IS'!K8 -> 27779.517 | AE27: ='Balance Sheet Build'!L45*'annual IS'!L8 -> 29330.648
B28: Deferred tax liability | C28: 119729 | D28: 124748 | E28: 115306 | F28: 110400 | G28: 99846 | H28: =G28 -> 99846 | I28: 95376 | J28: =(92288*(1))*1 -> 92288 | K28: 89281 | L28: 82665 | M28: =L28 -> 82665 | N28: 81927 | O28: 74527 | P28: 66737 | Q28: 68670 | R28: =Q28 -> 68670 | S28: 63282 | T28: 63466 | U28: 58605 | V28: 55834 | W28: =V28 -> 55834 | X28: 57158 | Y28: 86615 | Z28: 101573 | AA28: ='Balance Sheet Build'!H47*'annual IS'!H8 -> 55633.264 | AB28: ='Balance Sheet Build'!I47*'annual IS'!I8 -> 53096.461 | AC28: ='Balance Sheet Build'!J47*'annual IS'!J8 -> 49503.717 | AD28: ='Balance Sheet Build'!K47*'annual IS'!K8 -> 43922.154 | AE28: ='Balance Sheet Build'!L47*'annual IS'!L8 -> 37636.945
B29: Total long-term liabilities | C29: =SUM(C25:C28) -> 1126978 | D29: =SUM(D25:D28) -> 1121295 | E29: =SUM(E25:E28) -> 1100844 | F29: =SUM(F25:F28) -> 1120690 | G29: =SUM(G25:G28) -> 1101340 | H29: =SUM(H25:H28) -> 1101340 | I29: =SUM(I25:I28) -> 1092153 | J29: =SUM(J25:J28) -> 1083611 | ... AE29: =SUM(AE25:AE28) -> 1472682.8
B30: Total liabilities | C30: =SUM(C29,C23) -> 1331679 | D30: =SUM(D29,D23) -> 1313599 | E30: =SUM(E29,E23) -> 1285968 | F30: =SUM(F29,F23) -> 1227764 | G30: =SUM(G29,G23) -> 1254527 | H30: =G30 -> 1254527 | I30: =SUM(I29,I23) -> 1209804 | J30: =SUM(J29,J23) -> 1209128 | K30: =SUM(K29,K23) -> 1181639 | L30: =SUM(L29,L23) -> 1193260 | M30: =L30 -> 1193260 | N30: =SUM(N29,N23) -> 1116417 | O30: =SUM(O29,O23) -> 1116842 | P30: =SUM(P29,P23) -> 1105534 | Q30: =SUM(Q29,Q23) -> 1128769 | R30: =Q30 -> 1128769 | S30: =SUM(S29,S23) -> 1148700 | T30: =SUM(T29,T23) -> 1357429 | U30: =SUM(U29,U23) -> 1363660 | V30: =SUM(V29,V23) -> 1333639 | W30: =V30 -> 1333639 | X30: =SUM(X29,X23) -> 1292467 | Y30: =SUM(Y29,Y23) -> 1270257 | Z30: =SUM(Z29,Z23) -> 1264035 | AA30: =AA29+AA23 -> 1447171.6 | AB30: =AB29+AB23 -> 1524563.9 | AC30: =AC29+AC23 -> 1599255.5 | AD30: =AD29+AD23 -> 1636545.8 | AE30: =AE29+AE23 -> 1675409.3
B31: Stockholders’ equity
B32: Preferred stock, | H32: =G32 -> 0 | M32: =L32 -> 0 | R32: =Q32 -> 0 | W32: =V32 -> 0 | AA32: 0 | AB32: 0 | AC32: 0 | AD32: 0 | AE32: 0
B33: Common stock, | C33: 8 | D33: 8 | E33: 8 | F33: 8 | G33: 8 | H33: =G33 -> 8 | I33: 8 | J33: =(8*(1))*1 -> 8 | K33: 8 | L33: 8 | M33: =L33 -> 8 | N33: 9 | O33: 9 | P33: 9 | Q33: 9 | R33: =Q33 -> 9 | S33: 9 | T33: 9 | U33: 9 | V33: 9 | W33: =V33 -> 9 | X33: 9 | Y33: 9 | Z33: 9 | AA33: =W33 -> 9 | AB33: =X33 -> 9 | AC33: =Y33 -> 9 | AD33: =Z33 -> 9 | AE33: =AA33 -> 9
B34: Additional paid-in capital | C34: 1158372 | D34: 1630529 | E34: 1648743 | F34: 1662965 | G34: 1676508 | H34: =G34 -> 1676508 | I34: 1692835 | J34: =(1713122*(1))*1 -> 1713122 | K34: 1732985 | L34: 1745716 | M34: =L34 -> 1745716 | N34: 1764573 | O34: 1785014 | P34: 1808695 | Q34: 1829384 | R34: =Q34 -> 1829384 | S34: 1863334 | T34: 1886765 | U34: 1893088 | V34: 1905628 | W34: =V34 -> 1905628 | X34: 1905444 | Y34: 1919312 | Z34: 1917244 | AA34: ='Balance Sheet Build'!H54 -> 2001626.5 | AB34: ='Balance Sheet Build'!I54 -> 2105783.4 | AC34: ='Balance Sheet Build'!J54 -> 2218288.7 | AD34: ='Balance Sheet Build'!K54 -> 2336916.7 | AE34: ='Balance Sheet Build'!L54 -> 2462168.5
B35: Accumulated Other Comprehensive Earnings | H35: =G35 -> 0 | M35: =L35 -> 0 | R35: =Q35 -> 0 | W35: =V35 -> 0 | Y35: 203 | Z35: 8837 | AA35: 0 | AB35: =AA35 -> 0 | AC35: =AB35 -> 0 | AD35: =AC35 -> 0 | AE35: =AD35 -> 0
B36: Accumulated earnings | C36: 220348 | D36: 217733 | E36: 213915 | F36: 208877 | G36: 176059 | H36: =G36 -> 176059 | I36: 162420 | J36: =(151766*(1))*1 -> 151766 | K36: 150125 | L36: 149916 | M36: =L36 -> 149916 | N36: 154010 | O36: 164591 | P36: 179264 | Q36: 205628 | R36: =Q36 -> 205628 | S36: 234441 | T36: 270263 | U36: 231590 | V36: 209274 | W36: =V36 -> 209274 | X36: 218353 | Y36: 226897 | Z36: 207936 | AA36: ='Balance Sheet Build'!H61 -> 352943.77 | AB36: ='Balance Sheet Build'!I61 -> 525248.3 | AC36: ='Balance Sheet Build'!J61 -> 724137.51 | AD36: ='Balance Sheet Build'!K61 -> 939045.05 | AE36: ='Balance Sheet Build'!L61 -> 1171938.4
B37: Total stockholders’ equity | C37: =SUM(C33:C36) -> 1378728 | D37: =SUM(D33:D36) -> 1848270 | E37: =SUM(E33:E36) -> 1862666 | F37: =SUM(F33:F36) -> 1871850 | G37: =SUM(G33:G36) -> 1852575 | H37: =G37 -> 1852575 | I37: =SUM(I33:I36) -> 1855263 | J37: =SUM(J33:J36) -> 1864896 | K37: =SUM(K33:K36) -> 1883118 | L37: =SUM(L33:L36) -> 1895640 | M37: =L37 -> 1895640 | N37: =SUM(N33:N36) -> 1918592 | O37: =SUM(O33:O36) -> 1949614 | P37: =SUM(P33:P36) -> 1987968 | Q37: =SUM(Q33:Q36) -> 2035021 | R37: =Q37 -> 2035021 | S37: =SUM(S33:S36) -> 2097784 | T37: =SUM(T33:T36) -> 2157037 | U37: =SUM(U33:U36) -> 2124687 | V37: =SUM(V33:V36) -> 2114911 | W37: =V37 -> 2114911 | X37: =SUM(X33:X36) -> 2123806 | Y37: =SUM(Y33:Y36) -> 2146421 | Z37: =SUM(Z33:Z36) -> 2134026 | AA37: =SUM(AA32:AA36) -> 2354579.2 | AB37: =SUM(AB32:AB36) -> 2631040.7 | AC37: =SUM(AC32:AC36) -> 2942435.2 | AD37: =SUM(AD32:AD36) -> 3275970.7 | AE37: =SUM(AE32:AE36) -> 3634115.9
B38: Total liabilities and stockholders’ equity | C38: =SUM(C37,C30) -> 2710407 | D38: =SUM(D37,D30) -> 3161869 | E38: =SUM(E37,E30) -> 3148634 | F38: =SUM(F37,F30) -> 3099614 | G38: =SUM(G37,G30) -> 3107102 | H38: =G38 -> 3107102 | I38: =SUM(I37,I30) -> 3065067 | J38: =SUM(J37,J30) -> 3074024 | K38: =SUM(K37,K30) -> 3064757 | L38: =SUM(L37,L30) -> 3088900 | M38: =L38 -> 3088900 | N38: =SUM(N37,N30) -> 3035009 | O38: =SUM(O37,O30) -> 3066456 | P38: =SUM(P37,P30) -> 3093502 | Q38: =SUM(Q37,Q30) -> 3163790 | R38: =Q38 -> 3163790 | S38: =SUM(S37,S30) -> 3246484 | T38: =SUM(T37,T30) -> 3514466 | U38: =SUM(U37,U30) -> 3488347 | V38: =SUM(V37,V30) -> 3448550 | W38: =V38 -> 3448550 | X38: =SUM(X37,X30) -> 3416273 | Y38: =SUM(Y37,Y30) -> 3416678 | Z38: =SUM(Z37,Z30) -> 3398061 | AA38: =AA37+AA30 -> 3801750.8 | AB38: =AB37+AB30 -> 4155604.6 | AC38: =AC37+AC30 -> 4541690.7 | AD38: =AD37+AD30 -> 4912516.5 | AE38: =AE37+AE30 -> 5309525.2
B40: CHECK | C40: =C38-C15 -> 0 | D40: =D38-D15 -> 0 | E40: =E38-E15 -> 0 | F40: =F38-F15 -> 0 | G40: =G38-G15 -> 0 | H40: =H38-H15 -> 0 | I40: =I38-I15 -> 0 | J40: =J38-J15 -> 0 | ... AE40: =AE38-AE15 -> 0.47429685

Sheet Expense Build
B1: Expense Build- USD($) and shares in thousands | C1: Actual | AA1: Expected
C2: 2020A | D2: 2021 Q1 | E2: 2021 Q2 | F2: 2021 Q3 | G2: 2021 Q4 | H2: 2021A | I2: 2022 Q1 | J2: 2022 Q2 | K2: 2022 Q3 | L2: 2022 Q4 | M2: 2022A | N2: 2023 Q1 | O2: 2023 Q2 | P2: 2023 Q3 | Q2: 2023 Q4 | R2: 2023A | S2: 2024 Q1 | T2: 2024 Q2 | U2: 2024 Q3 | V2: 2024 Q4 | W2: 2024A | X2: 2024A | Y2: 2024A | Z2: 2024A | AA2: 2025 | AB2: =AA2+1 -> 2026 | AC2: =AB2+1 -> 2027 | AD2: =AC2+1 -> 2028 | AE2: =AD2+1 -> 2029
B4: Operating Expenses:
B5: Service Costs | C5: ='quarterly IS'!C11 -> 280214 | D5: ='quarterly IS'!D11 -> 70632 | E5: ='quarterly IS'!E11 -> 67334 | F5: ='quarterly IS'!F11 -> 66217 | G5: ='quarterly IS'!G11 -> 86119 | H5: ='quarterly IS'!H11 -> 290302 | I5: ='quarterly IS'!I11 -> 80874 | J5: ='quarterly IS'!J11 -> 74914 | ... Z5: ='quarterly IS'!Z11 -> 76889 | AA5: =AA27*'annual IS'!H5 -> 353773.74 | AB5: =AB27*'annual IS'!I5 -> 369088.02 | AC5: =AC27*'annual IS'!J5 -> 386377.51 | AD5: =AD27*'annual IS'!K5 -> 404985.21 | AE5: =AE27*'annual IS'!L5 -> 425264.57
B6: Custodial Costs | C6: ='quarterly IS'!C12 -> 19574 | D6: ='quarterly IS'!D12 -> 5009 | E6: ='quarterly IS'!E12 -> 4824 | F6: ='quarterly IS'!F12 -> 5734 | G6: ='quarterly IS'!G12 -> 6300 | H6: ='quarterly IS'!H12 -> 21867 | I6: ='quarterly IS'!I12 -> 6641 | J6: ='quarterly IS'!J12 -> 7090 | ... Z6: ='quarterly IS'!Z12 -> 10879 | AA6: =AA28*'annual IS'!H6 -> 48163.24 | AB6: =AB28*'annual IS'!I6 -> 50872.582 | AC6: =AC28*'annual IS'!J6 -> 52628.822 | AD6: =AD28*'annual IS'!K6 -> 51576.479 | AE6: =AE28*'annual IS'!L6 -> 50189.213
B7: Interchange Costs | C7: ='quarterly IS'!C13 -> 18448 | D7: ='quarterly IS'!D13 -> 5445 | E7: ='quarterly IS'!E13 -> 4974 | F7: ='quarterly IS'!F13 -> 4683 | G7: ='quarterly IS'!G13 -> 5579 | H7: ='quarterly IS'!H13 -> 20681 | I7: ='quarterly IS'!I13 -> 6991 | J7: ='quarterly IS'!J13 -> 6326 | ... Z7: ='quarterly IS'!Z13 -> 6333 | AA7: =AA29*'annual IS'!H7 -> 31520.695 | AB7: =AB29*'annual IS'!I7 -> 33342.741 | AC7: =AC29*'annual IS'!J7 -> 35395.973 | AD7: =AD29*'annual IS'!K7 -> 37628.696 | AE7: =AE29*'annual IS'!L7 -> 40081.359
B8: Total COGS | C8: =SUM(C5:C7) -> 318236 | D8: =SUM(D5:D7) -> 81086 | E8: =SUM(E5:E7) -> 77132 | F8: =SUM(F5:F7) -> 76634 | G8: =SUM(G5:G7) -> 97998 | H8: =SUM(H5:H7) -> 332850 | I8: =SUM(I5:I7) -> 94506 | J8: =SUM(J5:J7) -> 88330 | ... AE8: =SUM(AE5:AE7) -> 515535.14
B10: Sales and marketing | C10: ='quarterly IS'!C19 -> 49964 | D10: ='quarterly IS'!D19 -> 14086 | E10: ='quarterly IS'!E19 -> 15476 | F10: ='quarterly IS'!F19 -> 12726 | G10: ='quarterly IS'!G19 -> 16317 | H10: ='quarterly IS'!H19 -> 58605 | I10: ='quarterly IS'!I19 -> 16560 | J10: ='quarterly IS'!J19 -> 15843 | ... Z10: ='quarterly IS'!Z19 -> 24411 | AA10: =AA32*'annual IS'!$H$8 -> 101899.84 | AB10: =AB32*'annual IS'!$I$8 -> 110562.19 | AC10: =AC32*'annual IS'!$J$8 -> 119423.88 | AD10: =AD32*'annual IS'!$K$8 -> 125923.07 | AE10: =AE32*'annual IS'!$L$8 -> 132954.27
B11: Technology and development | C11: ='quarterly IS'!C20 -> 124809 | D11: ='quarterly IS'!D20 -> 35469 | E11: ='quarterly IS'!E20 -> 37898 | F11: ='quarterly IS'!F20 -> 38070 | G11: ='quarterly IS'!G20 -> 45927 | H11: ='quarterly IS'!H20 -> 157364 | I11: ='quarterly IS'!I20 -> 45183 | J11: ='quarterly IS'!J20 -> 46580 | ... Z11: ='quarterly IS'!Z20 -> 65916 | AA11: =AA33*'annual IS'!$H$8 -> 273517.1 | AB11: =AB33*'annual IS'!$I$8 -> 296768.37 | AC11: =AC33*'annual IS'!$J$8 -> 320554.72 | AD11: =AD33*'annual IS'!$K$8 -> 337999.69 | AE11: =AE33*'annual IS'!$L$8 -> 356872.66
B12: General and administrative | C12: ='quarterly IS'!C21 -> 84493 | D12: ='quarterly IS'!D21 -> 20687 | E12: ='quarterly IS'!E21 -> 22812 | F12: ='quarterly IS'!F21 -> 20004 | G12: ='quarterly IS'!G21 -> 20876 | H12: ='quarterly IS'!H21 -> 84379 | I12: ='quarterly IS'!I21 -> 23727 | J12: ='quarterly IS'!J21 -> 25937 | ... Z12: ='quarterly IS'!Z21 -> 30880 | AA12: =AA34*'annual IS'!$H$8 -> 148336.32 | AB12: =AB34*'annual IS'!$I$8 -> 160946.17 | AC12: =AC34*'annual IS'!$J$8 -> 173846.19 | AD12: =AD34*'annual IS'!$K$8 -> 183307.11 | AE12: =AE34*'annual IS'!$L$8 -> 193542.47
B13: Amortization of acquired intangible assets | C13: ='quarterly IS'!C22 -> 76064 | D13: ='quarterly IS'!D22 -> 19814 | E13: ='quarterly IS'!E22 -> 20289 | F13: ='quarterly IS'!F22 -> 19642 | G13: ='quarterly IS'!G22 -> 23046 | H13: ='quarterly IS'!H22 -> 82791 | I13: ='quarterly IS'!I22 -> 23698 | J13: ='quarterly IS'!J22 -> 24181 | ... Z13: ='quarterly IS'!Z22 -> 27002 | AA13: =AA35*'annual IS'!$H$8 -> 136329.18 | AB13: =AB35*'annual IS'!$I$8 -> 147918.31 | AC13: =AC35*'annual IS'!$J$8 -> 159774.14 | AD13: =AD35*'annual IS'!$K$8 -> 168469.24 | AE13: =AE35*'annual IS'!$L$8 -> 177876.1
B14: Merger Integration | C14: ='quarterly IS'!C23 -> 45990 | D14: ='quarterly IS'!D23 -> 8807 | E14: ='quarterly IS'!E23 -> 16371 | F14: ='quarterly IS'!F23 -> 13244 | G14: ='quarterly IS'!G23 -> 26383 | H14: ='quarterly IS'!H23 -> 64805 | I14: ='quarterly IS'!I23 -> 9294 | J14: ='quarterly IS'!J23 -> 7683 | ... Z14: ='quarterly IS'!Z23 -> 1159 | AA14: 4710 | AB14: 0 | AC14: 0 | AD14: 0 | AE14: 0
B15: Total Operating Expenses: | C15: =SUM(C10:C14) -> 381320 | D15: =SUM(D10:D14) -> 98863 | E15: =SUM(E10:E14) -> 112846 | F15: =SUM(F10:F14) -> 103686 | G15: =SUM(G10:G14) -> 132549 | H15: =SUM(H10:H14) -> 447944 | I15: =SUM(I10:I14) -> 118462 | J15: =SUM(J10:J14) -> 120224 | ... AE15: =SUM(AE10:AE14) -> 861245.5
B17: Non-operating Expenses:
B18: Interest expense (negative is expense) | C18: ='quarterly IS'!C30 -> -34881 | D18: ='quarterly IS'!D30 -> -6689 | E18: ='quarterly IS'!E30 -> -7254 | F18: ='quarterly IS'!F30 -> -11881 | G18: ='quarterly IS'!G30 -> -10748 | H18: ='quarterly IS'!H30 -> -36572 | I18: ='quarterly IS'!I30 -> -10461 | J18: ='quarterly IS'!J30 -> -11493 | ... Z18: ='quarterly IS'!Z30 -> -14049 | AA18: =AA38*'[1]Balance Sheet'!AA25 -> -57102.601 | AB18: =AB38*'[1]Balance Sheet'!AB25 -> -60516.648 | AC18: =AC38*'[1]Balance Sheet'!AC25 -> -63811.542 | AD18: =AD38*'[1]Balance Sheet'!AD25 -> -65643.997 | AE18: =AE38*'[1]Balance Sheet'!AE25 -> -67577.543
B19: Other income, net (negative is expense) | C19: ='quarterly IS'!C31 -> 5007 | D19: ='quarterly IS'!D31 -> -3630 | E19: ='quarterly IS'!E31 -> 344 | F19: ='quarterly IS'!F31 -> 3122 | G19: ='quarterly IS'!G31 -> -5767 | H19: ='quarterly IS'!H31 -> -5931 | I19: ='quarterly IS'!I31 -> -301 | J19: ='quarterly IS'!J31 -> 32 | ... Z19: ='quarterly IS'!Z31 -> 2886 | AA19: ='[1]annual IS'!H31 -> 5627.4461 | AB19: ='[1]annual IS'!I31 -> 6105.8267 | AC19: ='[1]annual IS'!J31 -> 6595.2161 | AD19: ='[1]annual IS'!K31 -> 6954.1357 | AE19: ='[1]annual IS'!L31 -> 7342.4353
B20: Provision for income taxes (benefit) | C20: ='quarterly IS'!C34 -> -4694 | D20: ='quarterly IS'!D34 -> -3451 | E20: ='quarterly IS'!E34 -> -3967 | F20: ='quarterly IS'!F34 -> -4087 | G20: ='quarterly IS'!G34 -> -10947 | H20: ='quarterly IS'!H34 -> -22452 | I20: ='quarterly IS'!I34 -> -4412 | J20: ='quarterly IS'!J34 -> -3219 | ... Z20: ='quarterly IS'!Z34 -> 15840 | AA20: ='[1]annual IS'!H34 -> 45968.257 | AB20: ='[1]annual IS'!I34 -> 57006.796 | AC20: ='[1]annual IS'!J34 -> 65591.125 | AD20: ='[1]annual IS'!K34 -> 71635.847 | AE20: ='[1]annual IS'!L34 -> 77631.118
B21: Total Non-operating Expenses: | C21: =-C18+-C19+C20 -> 25180 | D21: =-D18+-D19+D20 -> 6868 | E21: =-E18+-E19+E20 -> 2943 | F21: =-F18+-F19+F20 -> 4672 | G21: =-G18+-G19+G20 -> 5568 | H21: =-H18+-H19+H20 -> 20051 | I21: =-I18+-I19+I20 -> 6350 | J21: =-J18+-J19+J20 -> 8242 | ... AE21: =-AE18+-AE19+AE20 -> 137866.23
B23: Total Expenses: | C23: =SUM(C21,C15,C8) -> 724736 | D23: =SUM(D21,D15,D8) -> 186817 | E23: =SUM(E21,E15,E8) -> 192921 | F23: =SUM(F21,F15,F8) -> 184992 | G23: =SUM(G21,G15,G8) -> 236115 | H23: =SUM(H21,H15,H8) -> 800845 | I23: =SUM(I21,I15,I8) -> 219318 | J23: =SUM(J21,J15,J8) -> 216796 | ... AE23: =SUM(AE21,AE15,AE8) -> 1514646.9
B25: Expense Build Drivers:
B26: COGS Drivers:
B27: Service Costs - % of service revenue | C27: =C5/'annual IS'!C5 -> 0.65019978 | D27: =D5/'annual IS'!D5 -> 0.16544939 | E27: =E5/'annual IS'!E5 -> 0.14896046 | F27: =F5/'annual IS'!F5 -> 0.14531151 | G27: =G5/'annual IS'!G5 -> 0.18004587 | H27: =H5/'annual IS'!D5 -> 0.6800075 | I27: =I5/'annual IS'!I5 -> 0.15995648 | J27: =J5/'annual IS'!J5 -> 0.14347719 | K27: =K5/'annual IS'!K5 -> 0.14165888 | L27: =L5/'annual IS'!L5 -> 0.15411253 | M27: =M5/'annual IS'!E5 -> 0.70464088 | N27: =N5/'annual IS'!N5 -> #DIV/0! | O27: =O5/'annual IS'!O5 -> #DIV/0! | P27: =P5/'annual IS'!P5 -> #DIV/0! | Q27: =Q5/'annual IS'!Q5 -> #DIV/0! | R27: =R5/'annual IS'!F5 -> 0.69643178 | S27: =S5/'annual IS'!S5 -> #DIV/0! | T27: =T5/'annual IS'!T5 -> #DIV/0! | U27: =U5/'annual IS'!U5 -> #DIV/0! | V27: =V5/'annual IS'!V5 -> #DIV/0! | W27: =W5/'annual IS'!G5 -> 0.73505228 | X27: =X5/'quarterly IS'!X4 -> 0.73469132 | Y27: =Y5/'quarterly IS'!Y4 -> 0.63760149 | Z27: =Z5/'quarterly IS'!Z4 -> 0.6392182 | AA27: 0.72 | AB27: =AA27+$AF$27 -> 0.73 | AC27: =AB27+$AF$27 -> 0.74 | AD27: =AC27+$AF$27 -> 0.75 | AE27: =AD27+$AF$27 -> 0.76 | AF27: 0.01 | AG27: (+)
B28: Custodial Costs - % of custodial revenue | C28: =C6/'annual IS'!C6 -> 0.10251764 | D28: =D6/'quarterly IS'!D5 -> 0.10662438 | E28: =E6/'quarterly IS'!E5 -> 0.098901099 | F28: =F6/'quarterly IS'!F5 -> 0.11700608 | G28: =G6/'quarterly IS'!G5 -> 0.10851405 | H28: =H6/'annual IS'!D6 -> 0.10781641 | I28: =I6/'annual IS'!I6 -> 0.0088432831 | J28: =J6/'annual IS'!J6 -> 0.0084525397 | K28: =K6/'annual IS'!K6 -> 0.0076264354 | L28: =L6/'annual IS'!L6 -> 0.0058407984 | M28: =M6/'annual IS'!E6 -> 0.099895898 | N28: =N6/'annual IS'!N6 -> #DIV/0! | O28: =O6/'annual IS'!O6 -> #DIV/0! | P28: =P6/'annual IS'!P6 -> #DIV/0! | Q28: =Q6/'annual IS'!Q6 -> #DIV/0! | R28: =R6/'annual IS'!F6 -> 0.084072696 | S28: =S6/'annual IS'!S6 -> #DIV/0! | T28: =T6/'annual IS'!T6 -> #DIV/0! | U28: =U6/'annual IS'!U6 -> #DIV/0! | V28: =V6/'annual IS'!V6 -> #DIV/0! | W28: =W6/'annual IS'!G6 -> 0.072742907 | X28: =X6/'quarterly IS'!X5 -> 0.068690678 | Y28: =Y6/'quarterly IS'!Y5 -> 0.069660237 | Z28: =Z6/'quarterly IS'!Z5 -> 0.068392564 | AA28: =W28 -> 0.072742907 | AB28: =AA28-$AF$28 -> 0.067742907 | AC28: =AB28-$AF$28 -> 0.062742907 | AD28: =AC28-$AF$28 -> 0.057742907 | AE28: =AD28-$AF$28 -> 0.052742907 | AF28: 0.005 | AG28: (-)
B29: Interchange Cost - % of interchange revenue | C29: =C7/'annual IS'!C7 -> 0.16519956 | D29: =D7/'quarterly IS'!D6 -> 0.15696166 | E29: =E7/'quarterly IS'!E6 -> 0.15970461 | F29: =F7/'quarterly IS'!F6 -> 0.16597554 | G29: =G7/'quarterly IS'!G6 -> 0.17020043 | H29: =H7/'annual IS'!D7 -> 0.16306208 | I29: =I7/'annual IS'!I7 -> 0.035549555 | J29: =J7/'annual IS'!J7 -> 0.030302014 | K29: =K7/'annual IS'!K7 -> 0.026688166 | L29: =L7/'annual IS'!L7 -> 0.025194655 | M29: =M7/'annual IS'!E7 -> 0.16973861 | N29: =N7/'annual IS'!N7 -> #DIV/0! | O29: =O7/'annual IS'!O7 -> #DIV/0! | P29: =P7/'annual IS'!P7 -> #DIV/0! | Q29: =Q7/'annual IS'!Q7 -> #DIV/0! | R29: =R7/'annual IS'!F7 -> 0.17222176 | S29: =S7/'annual IS'!S7 -> #DIV/0! | T29: =T7/'annual IS'!T7 -> #DIV/0! | U29: =U7/'annual IS'!U7 -> #DIV/0! | V29: =V7/'annual IS'!V7 -> #DIV/0! | W29: =W7/'annual IS'!G7 -> 0.17752481 | X29: =X7/'quarterly IS'!X6 -> 0.14249611 | Y29: =Y7/'quarterly IS'!Y6 -> 0.14447032 | Z29: =Z7/'quarterly IS'!Z6 -> 0.14792927 | AA29: =AVERAGE(C29,H29,M29,R29,W29) -> 0.16954936 | AB29: =AA29 -> 0.16954936 | AC29: =AB29 -> 0.16954936 | AD29: =AC29 -> 0.16954936 | AE29: =AD29 -> 0.16954936
D30: =SUM(D27:D29) -> 0.42903543 | E30: =SUM(E27:E29) -> 0.40756616 | F30: =SUM(F27:F29) -> 0.42829313 | G30: =SUM(G27:G29) -> 0.45876035
B31: Operating Expense Drivers:
B32: Sales & Marketing - % of Revenue | C32: =C10/'annual IS'!C8 -> 0.068110746 | D32: =D10/'annual IS'!D8 -> 0.018618582 | E32: =E10/'annual IS'!E8 -> 0.017958846 | F32: =F10/'annual IS'!F8 -> 0.012731258 | G32: =G10/'annual IS'!G8 -> 0.013600061 | H32: =H10/'annual IS'!$D$8 -> 0.077462871 | I32: =I10/'annual IS'!I8 -> 0.01139538 | J32: =J10/'annual IS'!J8 -> 0.010093025 | K32: =K10/'annual IS'!K8 -> 0.010419167 | L32: =L10/'annual IS'!L8 -> 0.010987444 | M32: =M10/'annual IS'!$E$8 -> 0.079894586 | N32: =N10/'annual IS'!N8 -> #DIV/0! | O32: =O10/'annual IS'!O8 -> #DIV/0! | P32: =P10/'annual IS'!P8 -> #DIV/0! | Q32: =Q10/'annual IS'!Q8 -> #DIV/0! | R32: =R10/'annual IS'!$F$8 -> 0.079305753 | S32: =S10/'annual IS'!S8 -> #DIV/0! | T32: =T10/'annual IS'!T8 -> #DIV/0! | U32: =U10/'annual IS'!U8 -> #DIV/0! | V32: =V10/'annual IS'!V8 -> #DIV/0! | W32: =W10/'annual IS'!$G$8 -> 0.075630077 | X32: =X10/'quarterly IS'!$D$7 -> 0.14106253 | Y32: =Y10/'quarterly IS'!$D$7 -> 0.10815301 | Z32: =Z10/'quarterly IS'!$D$7 -> 0.13252299 | AA32: =AVERAGE(C32,H32,M32,R32,W32) -> 0.076080807 | AB32: =AA32 -> 0.076080807 | AC32: =AB32 -> 0.076080807 | AD32: =AC32 -> 0.076080807 | AE32: =AD32 -> 0.076080807
B33: Technology & Development – % of Revenue | C33: =C11/'annual IS'!$C$8 -> 0.17013918 | H33: =H11/'annual IS'!$D$8 -> 0.20800047 | I33: =I11/'annual IS'!I9 -> 531511.71 | J33: =J11/'annual IS'!J9 -> 581151.55 | K33: =K11/'annual IS'!K9 -> 898363.12 | L33: =L11/'annual IS'!L9 -> 944208.82 | M33: =M11/'annual IS'!$E$8 -> 0.22439855 | N33: =N11/'annual IS'!N9 -> #DIV/0! | O33: =O11/'annual IS'!O9 -> #DIV/0! | P33: =P11/'annual IS'!P9 -> #DIV/0! | Q33: =Q11/'annual IS'!Q9 -> #DIV/0! | R33: =R11/'annual IS'!$F$8 -> 0.21890141 | S33: =S11/'annual IS'!S9 -> #DIV/0! | T33: =T11/'annual IS'!T9 -> #DIV/0! | U33: =U11/'annual IS'!U9 -> #DIV/0! | V33: =V11/'annual IS'!V9 -> #DIV/0! | W33: =W11/'annual IS'!$G$8 -> 0.19963176 | X33: =X11/'quarterly IS'!$D$7 -> 0.33352515 | Y33: =Y11/'quarterly IS'!$D$7 -> 0.35180943 | Z33: =Z11/'quarterly IS'!$D$7 -> 0.35784628 | AA33: =AVERAGE(C33,H33,M33,R33,W33) -> 0.20421427 | AB33: =AA33 -> 0.20421427 | AC33: =AB33 -> 0.20421427 | AD33: =AC33 -> 0.20421427 | AE33: =AD33 -> 0.20421427
